Workbook

Sheet CONDUITS
A1: [CONDUITS]
A2: ;;Name | B2: From Node | C2: To Node | D2: Length | E2: Roughness | F2: InOffset | G2: OutOffset | H2: InitFlow | I2: MaxFlow
A3: ;;-------------- | B3: ---------------- | C3: ---------------- | D3: ---------- | E3: ---------- | F3: ---------- | G3: ---------- | H3: ---------- | I3: ----------
A4: 158 | B4: 240 | C4: 347 | D4: 250 | E4: 0.01 | F4: 0 | G4: 0 | H4: 0 | I4: 0
A5: 163 | B5: 245 | C5: 240 | D5: 85 | E5: 0.01 | F5: 0 | G5: 2.0105 | H5: 0 | I5: 0
A6: 156 | B6: 239 | C6: 240 | D6: 220 | E6: 0.01 | F6: 0 | G6: 0.5 | H6: 0 | I6: 0
A7: 153 | B7: 236 | C7: 240 | D7: 85 | E7: 0.01 | F7: 0 | G7: 1.3035 | H7: 0 | I7: 0
A8: 152 | B8: 235 | C8: 236 | D8: 200 | E8: 0.01 | F8: 0 | G8: 1.9675 | H8: 0 | I8: 0
A9: 149 | B9: 232 | C9: 236 | D9: 85 | E9: 0.01 | F9: 0 | G9: 0 | H9: 0 | I9: 0
A10: 161 | B10: 243 | C10: 239 | D10: 80 | E10: 0.01 | F10: 0 | G10: 5.007 | H10: 0 | I10: 0
A11: 155 | B11: 238 | C11: 239 | D11: 210 | E11: 0.01 | F11: 0 | G11: 0 | H11: 0 | I11: 0
A12: 169 | B12: 250 | C12: 245 | D12: 85 | E12: 0.01 | F12: 0 | G12: 0 | H12: 0 | I12: 0
A13: 162 | B13: 244 | C13: 245 | D13: 170 | E13: 0.01 | F13: 0 | G13: 4.437 | H13: 0 | I13: 0
A14: 148 | B14: 231 | C14: 232 | D14: 190 | E14: 0.01 | F14: 0 | G14: 1.6 | H14: 0 | I14: 0
A15: 144 | B15: 228 | C15: 232 | D15: 85 | E15: 0.01 | F15: 0 | G15: 0.0915 | H15: 0 | I15: 0
... A18: 160 | B18: 242 | C18: 243 | D18: 215 | E18: 0.01 | F18: 0 | G18: 0.13 | H18: 0 | I18: 0
A19: 450 | B19: z_0512_001_101 | C19: 244 | D19: 70 | E19: 0.01 | F19: 0 | G19: 0 | H19: 0 | I19: 0
A20: 177 | B20: 258 | C20: 250 | D20: 160 | E20: 0.01 | F20: 0 | G20: 0 | H20: 0 | I20: 0
A21: 167 | B21: 249 | C21: 250 | D21: 155 | E21: 0.01 | F21: 0 | G21: 0.9545 | H21: 0 | I21: 0
A22: 143 | B22: 227 | C22: 228 | D22: 185 | E22: 0.01 | F22: 0 | G22: 2.0895 | H22: 0 | I22: 0
A23: 137 | B23: 221 | C23: 228 | D23: 85 | E23: 0.01 | F23: 0 | G23: 0 | H23: 0 | I23: 0
A24: 147 | B24: 230 | C24: 231 | D24: 190 | E24: 0.01 | F24: 0 | G24: 0 | H24: 0 | I24: 0
A25: 150 | B25: 233 | C25: 234 | D25: 200 | E25: 0.01 | F25: 0 | G25: 0.05 | H25: 0 | I25: 0
A26: 448 | B26: z_0512_001_099 | C26: 237 | D26: 80 | E26: 0.01 | F26: 0 | G26: 6.101 | H26: 0 | I26: 0
A27: 159 | B27: 241 | C27: 237 | D27: 80 | E27: 0.01 | F27: 0 | G27: 0.9 | H27: 0 | I27: 0
A28: 87 | B28: 177 | C28: 237 | D28: 220 | E28: 0.01 | F28: 0 | G28: 0.205786 | H28: 0 | I28: 0
A29: 449 | B29: z_0512_001_100 | C29: 242 | D29: 215 | E29: 0.01 | F29: 0 | G29: 0.05 | H29: 0 | I29: 0
A30: 451 | B30: z_0512_001_102 | C30: 249 | D30: 90 | E30: 0.01 | F30: 0 | G30: 3.5125 | H30: 0 | I30: 0
A31: 166 | B31: 248 | C31: 249 | D31: 215 | E31: 0.01 | F31: 0 | G31: 0 | H31: 0 | I31: 0
A32: 183 | B32: 263 | C32: 258 | D32: 80 | E32: 0.01 | F32: 0 | G32: 0 | H32: 0 | I32: 0
A33: 176 | B33: 257 | C33: 258 | D33: 200 | E33: 0.01 | F33: 0 | G33: 3.5905 | H33: 0 | I33: 0
A34: 138 | B34: 222 | C34: 221 | D34: 170 | E34: 0.01 | F34: 0 | G34: 2.199 | H34: 0 | I34: 0
A35: 136 | B35: 220 | C35: 221 | D35: 85 | E35: 0.01 | F35: 0 | G35: 0.5 | H35: 0 | I35: 0
A36: 142 | B36: 226 | C36: 227 | D36: 185 | E36: 0.01 | F36: 0 | G36: 0 | H36: 0 | I36: 0
A37: 145 | B37: 229 | C37: 230 | D37: 190 | E37: 0.01 | F37: 0 | G37: 0 | H37: 0 | I37: 0
A38: 446 | B38: z_0512_001_097 | C38: 233 | D38: 80 | E38: 0.01 | F38: 0 | G38: 2.0155 | H38: 0 | I38: 0
A39: 88 | B39: 178 | C39: 233 | D39: 220 | E39: 0.01 | F39: 0 | G39: 0 | H39: 0 | I39: 0
A40: 86 | B40: 176 | C40: 177 | D40: 80 | E40: 0.01 | F40: 0 | G40: 0.3 | H40: 0 | I40: 0
A41: 48 | B41: 141 | C41: 177 | D41: 225 | E41: 0.01 | F41: 0 | G41: 1.111714 | H41: 0 | I41: 0
A42: 419 | B42: z_0512_001_070 | C42: 241 | D42: 220 | E42: 0.01 | F42: 0 | G42: 4.659 | H42: 0 | I42: 0
...

Sheet XSECTIONS
A1: [XSECTIONS]
A2: ;;Link | B2: Shape | C2: Geom1 | D2: Geom2 | E2: Geom3 | F2: Geom4 | G2: Barrels Culvert
A3: ;;-------------- | B3: ------------ | C3: ---------------- | D3: ---------- | E3: ---------- | F3: ---------- | G3: ---------- ----------
A4: 158 | B4: CIRCULAR | C4: 2 | D4: 0 | E4: 0 | F4: 0 | G4: 1
A5: 163 | B5: CIRCULAR | C5: 0.8 | D5: 0 | E5: 0 | F5: 0 | G5: 1
A6: 156 | B6: CIRCULAR | C6: 1.5 | D6: 0 | E6: 0 | F6: 0 | G6: 1
A7: 153 | B7: CIRCULAR | C7: 2 | D7: 0 | E7: 0 | F7: 0 | G7: 1
A8: 152 | B8: CIRCULAR | C8: 0.4 | D8: 0 | E8: 0 | F8: 0 | G8: 1
A9: 149 | B9: CIRCULAR | C9: 2 | D9: 0 | E9: 0 | F9: 0 | G9: 1
A10: 161 | B10: CIRCULAR | C10: 0.53 | D10: 0 | E10: 0 | F10: 0 | G10: 1
A11: 155 | B11: CIRCULAR | C11: 1.5 | D11: 0 | E11: 0 | F11: 0 | G11: 1
A12: 169 | B12: CIRCULAR | C12: 0.8 | D12: 0 | E12: 0 | F12: 0 | G12: 1
A13: 162 | B13: CIRCULAR | C13: 0.35 | D13: 0 | E13: 0 | F13: 0 | G13: 1
A14: 148 | B14: CIRCULAR | C14: 0.4 | D14: 0 | E14: 0 | F14: 0 | G14: 1
A15: 144 | B15: CIRCULAR | C15: 2 | D15: 0 | E15: 0 | F15: 0 | G15: 1
... A533: 269 | B533: CIRCULAR | C533: 0.35 | D533: 0 | E533: 0 | F533: 0 | G533: 1

Sheet Capacity
A1: [Capacity] | E1: D-Max | F1: =MAX(C3:C532) -> 2 | G1: D-Min | H1: =MIN(C3:C532) -> 0.35 | K1: 2
A2: ;;Link | B2: Length(m) | C2: Geom1(m) | D2: Capacity | F2: Weighted-D | J2: Geom1(m) | K2: 1.5
A3: 158 | B3: 250 | C3: 2 | D3: =3.1415926*$B3*(($C3/2)^2) -> 785.39815 | F3: =$C3/$F$1 -> 1 | J3: 2 | K3: 1.2
A4: 163 | B4: 85 | C4: 0.8 | D4: =3.1415926*$B4*(($C4/2)^2) -> 42.725659 | F4: =$C4/$F$1 -> 0.4 | J4: 0.8 | K4: 1
A5: 156 | B5: 220 | C5: 1.5 | D5: =3.1415926*$B5*(($C5/2)^2) -> 388.77208 | F5: =$C5/$F$1 -> 0.75 | J5: 1.5 | K5: 0.8
A6: 153 | B6: 85 | C6: 2 | D6: =3.1415926*$B6*(($C6/2)^2) -> 267.03537 | F6: =$C6/$F$1 -> 1 | J6: 0.4 | K6: 0.6
A7: 152 | B7: 200 | C7: 0.4 | D7: =3.1415926*$B7*(($C7/2)^2) -> 25.132741 | F7: =$C7/$F$1 -> 0.2 | J7: 0.53 | K7: 0.53
A8: 149 | B8: 85 | C8: 2 | D8: =3.1415926*$B8*(($C8/2)^2) -> 267.03537 | F8: =$C8/$F$1 -> 1 | J8: 0.35 | K8: 0.4
A9: 161 | B9: 80 | C9: 0.53 | D9: =3.1415926*$B9*(($C9/2)^2) -> 17.649467 | F9: =$C9/$F$1 -> 0.265 | J9: 0.6 | K9: 0.35
A10: 155 | B10: 210 | C10: 1.5 | D10: =3.1415926*$B10*(($C10/2)^2) -> 371.10063 | F10: =$C10/$F$1 -> 0.75 | J10: 1.2
A11: 169 | B11: 85 | C11: 0.8 | D11: =3.1415926*$B11*(($C11/2)^2) -> 42.725659 | F11: =$C11/$F$1 -> 0.4 | J11: 1
A12: 162 | B12: 170 | C12: 0.35 | D12: =3.1415926*$B12*(($C12/2)^2) -> 16.355916 | F12: =$C12/$F$1 -> 0.175
A13: 148 | B13: 190 | C13: 0.4 | D13: =3.1415926*$B13*(($C13/2)^2) -> 23.876104 | F13: =$C13/$F$1 -> 0.2
A14: 144 | B14: 85 | C14: 2 | D14: =3.1415926*$B14*(($C14/2)^2) -> 267.03537 | F14: =$C14/$F$1 -> 1
A15: 151 | B15: 200 | C15: 0.4 | D15: =3.1415926*$B15*(($C15/2)^2) -> 25.132741 | F15: =$C15/$F$1 -> 0.2
A16: 154 | B16: 220 | C16: 1.5 | D16: =3.1415926*$B16*(($C16/2)^2) -> 388.77208 | F16: =$C16/$F$1 -> 0.75
A17: 160 | B17: 215 | C17: 0.4 | D17: =3.1415926*$B17*(($C17/2)^2) -> 27.017696 | F17: =$C17/$F$1 -> 0.2
A18: 450 | B18: 70 | C18: 0.35 | D18: =3.1415926*$B18*(($C18/2)^2) -> 6.7347891 | F18: =$C18/$F$1 -> 0.175
A19: 177 | B19: 160 | C19: 1.5 | D19: =3.1415926*$B19*(($C19/2)^2) -> 282.74333 | F19: =$C19/$F$1 -> 0.75
A20: 167 | B20: 155 | C20: 1.2 | D20: =3.1415926*$B20*(($C20/2)^2) -> 175.30087 | F20: =$C20/$F$1 -> 0.6
A21: 143 | B21: 185 | C21: 0.35 | D21: =3.1415926*$B21*(($C21/2)^2) -> 17.799086 | F21: =$C21/$F$1 -> 0.175
A22: 137 | B22: 85 | C22: 2 | D22: =3.1415926*$B22*(($C22/2)^2) -> 267.03537 | F22: =$C22/$F$1 -> 1
A23: 147 | B23: 190 | C23: 0.4 | D23: =3.1415926*$B23*(($C23/2)^2) -> 23.876104 | F23: =$C23/$F$1 -> 0.2
... A532: 269 | B532: 120 | C532: 0.53 | D532: =3.1415926*$B532*(($C532/2)^2) -> 26.474201 | F532: =$C532/$F$1 -> 0.265

Sheet Sheet1
A1: ;;Link | B1: Volume | C1: Diameter | D1: Input | F1: Weighted-D | I1: Weighted-D | L1: Weighted-D | M1: SUM-UP | N1: SUM-Dup | O1: Output | Q1: Weighted-D | R1: SUM-D | S1: SUM-Dd | U1: Conduit | V1: I1 | W1: Upstreams | X1: Downstreams | AB1: A 1-1 | AC1: A 1-2 | AD1: A 2-1 | AE1: A 2-2 | AG1: A 1-3
A2: 158 | B2: =IFERROR(VLOOKUP(A2,Capacity!$A$3:$D$532,4,), "0") -> 785.39815 | C2: =IFERROR(VLOOKUP(A2,Capacity!$A$3:$F$532,6,), "0") -> 1 | D2: 156 | E2: =IFERROR(VLOOKUP(D2,Capacity!$A$3:$D$532,4,), "0") -> 388.77208 | F2: =IFERROR(VLOOKUP(D2,Capacity!$A$3:$F$532,6,), "0") -> 0.75 | G2: 163 | H2: =IFERROR(VLOOKUP(G2,Capacity!$A$3:$D$532,4,), "0") -> 42.725659 | I2: =IFERROR(VLOOKUP(G2,Capacity!$A$3:$F$532,6,), "0") -> 0.4 | J2: 153 | K2: =IFERROR(VLOOKUP(J2,Capacity!$A$3:$D$532,4,), "0") -> 267.03537 | L2: =IFERROR(VLOOKUP(J2,Capacity!$A$3:$F$532,6,), "0") -> 1 | M2: =$E2+$H2+$K2 -> 698.53311 | N2: =$F2+$I2+$L2 -> 2.15 | P2: =IFERROR(VLOOKUP(O2,Capacity!$A$3:$D$532,4,), "0") -> 0 | Q2: =IFERROR(VLOOKUP(O2,Capacity!$A$3:$F$532,6,), "0") -> 0 | R2: =$P2 -> 0 | S2: 0 | U2: 158 | V2: 3 | W2: 3 | X2: 0 | AB2: =($M2/$R2) -> #DIV/0! | AC2: =($M2/$B2) -> 0.8894 | AD2: =($N2/$S2) -> #DIV/0!
A3: 163 | B3: =IFERROR(VLOOKUP(A3,Capacity!$A$3:$D$532,4,), "0") -> 42.725659 | C3: =IFERROR(VLOOKUP(A3,Capacity!$A$3:$F$532,6,), "0") -> 0.4 | D3: 162 | E3: =IFERROR(VLOOKUP(D3,Capacity!$A$3:$D$532,4,), "0") -> 16.355916 | F3: =IFERROR(VLOOKUP(D3,Capacity!$A$3:$F$532,6,), "0") -> 0.175 | G3: 169 | H3: =IFERROR(VLOOKUP(G3,Capacity!$A$3:$D$532,4,), "0") -> 42.725659 | I3: =IFERROR(VLOOKUP(G3,Capacity!$A$3:$F$532,6,), "0") -> 0.4 | K3: =IFERROR(VLOOKUP(J3,Capacity!$A$3:$D$532,4,), "0") -> 0 | L3: =IFERROR(VLOOKUP(J3,Capacity!$A$3:$F$532,6,), "0") -> 0 | M3: =$E3+$H3+$K3 -> 59.081576 | N3: =$F3+$I3+$L3 -> 0.575 | O3: 158 | P3: =IFERROR(VLOOKUP(O3,Capacity!$A$3:$D$532,4,), "0") -> 785.39815 | Q3: =IFERROR(VLOOKUP(O3,Capacity!$A$3:$F$532,6,), "0") -> 1 | R3: =$P3 -> 785.39815 | S3: =$Q3 -> 1 | U3: 163 | V3: 3 | W3: 3 | X3: 1 | AB3: =($M3/$R3) -> 0.075225 | AC3: =($M3/$B3) -> 1.3828125 | AD3: =($N3/$S3) -> 0.575 | AE3: =($N3/$C3) -> 1.4375 | AG3: =$M3/($R3+$B3) -> 0.071343892
A4: 156 | B4: =IFERROR(VLOOKUP(A4,Capacity!$A$3:$D$532,4,), "0") -> 388.77208 | C4: =IFERROR(VLOOKUP(A4,Capacity!$A$3:$F$532,6,), "0") -> 0.75 | D4: 155 | E4: =IFERROR(VLOOKUP(D4,Capacity!$A$3:$D$532,4,), "0") -> 371.10063 | F4: =IFERROR(VLOOKUP(D4,Capacity!$A$3:$F$532,6,), "0") -> 0.75 | G4: 161 | H4: =IFERROR(VLOOKUP(G4,Capacity!$A$3:$D$532,4,), "0") -> 17.649467 | I4: =IFERROR(VLOOKUP(G4,Capacity!$A$3:$F$532,6,), "0") -> 0.265 | K4: =IFERROR(VLOOKUP(J4,Capacity!$A$3:$D$532,4,), "0") -> 0 | L4: =IFERROR(VLOOKUP(J4,Capacity!$A$3:$F$532,6,), "0") -> 0 | M4: =$E4+$H4+$K4 -> 388.75009 | N4: =$F4+$I4+$L4 -> 1.015 | O4: 158 | P4: =IFERROR(VLOOKUP(O4,Capacity!$A$3:$D$532,4,), "0") -> 785.39815 | Q4: =IFERROR(VLOOKUP(O4,Capacity!$A$3:$F$532,6,), "0") -> 1 | R4: =$P4 -> 785.39815 | S4: =$Q4 -> 1 | U4: 156 | V4: 3 | W4: 3 | X4: 1 | AB4: =($M4/$R4) -> 0.494972 | AC4: =($M4/$B4) -> 0.99994343 | AD4: =($N4/$S4) -> 1.015 | AE4: =($N4/$C4) -> 1.3533333 | AG4: =$M4/($R4+$B4) -> 0.33108495
A5: 153 | B5: =IFERROR(VLOOKUP(A5,Capacity!$A$3:$D$532,4,), "0") -> 267.03537 | C5: =IFERROR(VLOOKUP(A5,Capacity!$A$3:$F$532,6,), "0") -> 1 | D5: 152 | E5: =IFERROR(VLOOKUP(D5,Capacity!$A$3:$D$532,4,), "0") -> 25.132741 | F5: =IFERROR(VLOOKUP(D5,Capacity!$A$3:$F$532,6,), "0") -> 0.2 | G5: 149 | H5: =IFERROR(VLOOKUP(G5,Capacity!$A$3:$D$532,4,), "0") -> 267.03537 | I5: =IFERROR(VLOOKUP(G5,Capacity!$A$3:$F$532,6,), "0") -> 1 | K5: =IFERROR(VLOOKUP(J5,Capacity!$A$3:$D$532,4,), "0") -> 0 | L5: =IFERROR(VLOOKUP(J5,Capacity!$A$3:$F$532,6,), "0") -> 0 | M5: =$E5+$H5+$K5 -> 292.16811 | N5: =$F5+$I5+$L5 -> 1.2 | O5: 158 | P5: =IFERROR(VLOOKUP(O5,Capacity!$A$3:$D$532,4,), "0") -> 785.39815 | Q5: =IFERROR(VLOOKUP(O5,Capacity!$A$3:$F$532,6,), "0") -> 1 | R5: =$P5 -> 785.39815 | S5: =$Q5 -> 1 | U5: 153 | V5: 2 | W5: 2 | X5: 1 | AB5: =($M5/$R5) -> 0.372 | AC5: =($M5/$B5) -> 1.0941176 | AD5: =($N5/$S5) -> 1.2 | AE5: =($N5/$C5) -> 1.2 | AG5: =$M5/($R5+$B5) -> 0.27761194
A6: 152 | B6: =IFERROR(VLOOKUP(A6,Capacity!$A$3:$D$532,4,), "0") -> 25.132741 | C6: =IFERROR(VLOOKUP(A6,Capacity!$A$3:$F$532,6,), "0") -> 0.2 | D6: 151 | E6: =IFERROR(VLOOKUP(D6,Capacity!$A$3:$D$532,4,), "0") -> 25.132741 | F6: =IFERROR(VLOOKUP(D6,Capacity!$A$3:$F$532,6,), "0") -> 0.2 | H6: =IFERROR(VLOOKUP(G6,Capacity!$A$3:$D$532,4,), "0") -> 0 | I6: =IFERROR(VLOOKUP(G6,Capacity!$A$3:$F$532,6,), "0") -> 0 | K6: =IFERROR(VLOOKUP(J6,Capacity!$A$3:$D$532,4,), "0") -> 0 | L6: =IFERROR(VLOOKUP(J6,Capacity!$A$3:$F$532,6,), "0") -> 0 | M6: =$E6+$H6+$K6 -> 25.132741 | N6: =$F6+$I6+$L6 -> 0.2 | O6: 153 | P6: =IFERROR(VLOOKUP(O6,Capacity!$A$3:$D$532,4,), "0") -> 267.03537 | Q6: =IFERROR(VLOOKUP(O6,Capacity!$A$3:$F$532,6,), "0") -> 1 | R6: =$P6 -> 267.03537 | S6: =$Q6 -> 1 | U6: 152 | V6: 2 | W6: 2 | X6: 1 | AB6: =($M6/$R6) -> 0.094117647 | AC6: =($M6/$B6) -> 1 | AD6: =($N6/$S6) -> 0.2 | AE6: =($N6/$C6) -> 1 | AG6: =$M6/($R6+$B6) -> 0.086021505
A7: 149 | B7: =IFERROR(VLOOKUP(A7,Capacity!$A$3:$D$532,4,), "0") -> 267.03537 | C7: =IFERROR(VLOOKUP(A7,Capacity!$A$3:$F$532,6,), "0") -> 1 | D7: 148 | E7: =IFERROR(VLOOKUP(D7,Capacity!$A$3:$D$532,4,), "0") -> 23.876104 | F7: =IFERROR(VLOOKUP(D7,Capacity!$A$3:$F$532,6,), "0") -> 0.2 | G7: 144 | H7: =IFERROR(VLOOKUP(G7,Capacity!$A$3:$D$532,4,), "0") -> 267.03537 | I7: =IFERROR(VLOOKUP(G7,Capacity!$A$3:$F$532,6,), "0") -> 1 | K7: =IFERROR(VLOOKUP(J7,Capacity!$A$3:$D$532,4,), "0") -> 0 | L7: =IFERROR(VLOOKUP(J7,Capacity!$A$3:$F$532,6,), "0") -> 0 | M7: =$E7+$H7+$K7 -> 290.91147 | N7: =$F7+$I7+$L7 -> 1.2 | O7: 153 | P7: =IFERROR(VLOOKUP(O7,Capacity!$A$3:$D$532,4,), "0") -> 267.03537 | Q7: =IFERROR(VLOOKUP(O7,Capacity!$A$3:$F$532,6,), "0") -> 1 | R7: =$P7 -> 267.03537 | S7: =$Q7 -> 1 | U7: 149 | V7: 2 | W7: 2 | X7: 1 | AB7: =($M7/$R7) -> 1.0894118 | AC7: =($M7/$B7) -> 1.0894118 | AD7: =($N7/$S7) -> 1.2 | AE7: =($N7/$C7) -> 1.2 | AG7: =$M7/($R7+$B7) -> 0.54470588
A8: 161 | B8: =IFERROR(VLOOKUP(A8,Capacity!$A$3:$D$532,4,), "0") -> 17.649467 | C8: =IFERROR(VLOOKUP(A8,Capacity!$A$3:$F$532,6,), "0") -> 0.265 | D8: 160 | E8: =IFERROR(VLOOKUP(D8,Capacity!$A$3:$D$532,4,), "0") -> 27.017696 | F8: =IFERROR(VLOOKUP(D8,Capacity!$A$3:$F$532,6,), "0") -> 0.2 | H8: =IFERROR(VLOOKUP(G8,Capacity!$A$3:$D$532,4,), "0") -> 0 | I8: =IFERROR(VLOOKUP(G8,Capacity!$A$3:$F$532,6,), "0") -> 0 | K8: =IFERROR(VLOOKUP(J8,Capacity!$A$3:$D$532,4,), "0") -> 0 | L8: =IFERROR(VLOOKUP(J8,Capacity!$A$3:$F$532,6,), "0") -> 0 | M8: =$E8+$H8+$K8 -> 27.017696 | N8: =$F8+$I8+$L8 -> 0.2 | O8: 156 | P8: =IFERROR(VLOOKUP(O8,Capacity!$A$3:$D$532,4,), "0") -> 388.77208 | Q8: =IFERROR(VLOOKUP(O8,Capacity!$A$3:$F$532,6,), "0") -> 0.75 | R8: =$P8 -> 388.77208 | S8: =$Q8 -> 0.75 | U8: 161 | V8: 2 | W8: 2 | X8: 1 | AB8: =($M8/$R8) -> 0.069494949 | AC8: =($M8/$B8) -> 1.5307939 | AD8: =($N8/$S8) -> 0.26666667 | AE8: =($N8/$C8) -> 0.75471698 | AG8: =$M8/($R8+$B8) -> 0.066477027
A9: 155 | B9: =IFERROR(VLOOKUP(A9,Capacity!$A$3:$D$532,4,), "0") -> 371.10063 | C9: =IFERROR(VLOOKUP(A9,Capacity!$A$3:$F$532,6,), "0") -> 0.75 | D9: 154 | E9: =IFERROR(VLOOKUP(D9,Capacity!$A$3:$D$532,4,), "0") -> 388.77208 | F9: =IFERROR(VLOOKUP(D9,Capacity!$A$3:$F$532,6,), "0") -> 0.75 | H9: =IFERROR(VLOOKUP(G9,Capacity!$A$3:$D$532,4,), "0") -> 0 | I9: =IFERROR(VLOOKUP(G9,Capacity!$A$3:$F$532,6,), "0") -> 0 | K9: =IFERROR(VLOOKUP(J9,Capacity!$A$3:$D$532,4,), "0") -> 0 | L9: =IFERROR(VLOOKUP(J9,Capacity!$A$3:$F$532,6,), "0") -> 0 | M9: =$E9+$H9+$K9 -> 388.77208 | N9: =$F9+$I9+$L9 -> 0.75 | O9: 156 | P9: =IFERROR(VLOOKUP(O9,Capacity!$A$3:$D$532,4,), "0") -> 388.77208 | Q9: =IFERROR(VLOOKUP(O9,Capacity!$A$3:$F$532,6,), "0") -> 0.75 | R9: =$P9 -> 388.77208 | S9: =$Q9 -> 0.75 | U9: 155 | V9: 1 | W9: 1 | X9: 1 | AB9: =($M9/$R9) -> 1 | AC9: =($M9/$B9) -> 1.047619 | AD9: =($N9/$S9) -> 1 | AE9: =($N9/$C9) -> 1 | AG9: =$M9/($R9+$B9) -> 0.51162791
A10: 169 | B10: =IFERROR(VLOOKUP(A10,Capacity!$A$3:$D$532,4,), "0") -> 42.725659 | C10: =IFERROR(VLOOKUP(A10,Capacity!$A$3:$F$532,6,), "0") -> 0.4 | D10: 167 | E10: =IFERROR(VLOOKUP(D10,Capacity!$A$3:$D$532,4,), "0") -> 175.30087 | F10: =IFERROR(VLOOKUP(D10,Capacity!$A$3:$F$532,6,), "0") -> 0.6 | G10: 177 | H10: =IFERROR(VLOOKUP(G10,Capacity!$A$3:$D$532,4,), "0") -> 282.74333 | I10: =IFERROR(VLOOKUP(G10,Capacity!$A$3:$F$532,6,), "0") -> 0.75 | K10: =IFERROR(VLOOKUP(J10,Capacity!$A$3:$D$532,4,), "0") -> 0 | L10: =IFERROR(VLOOKUP(J10,Capacity!$A$3:$F$532,6,), "0") -> 0 | M10: =$E10+$H10+$K10 -> 458.0442 | N10: =$F10+$I10+$L10 -> 1.35 | O10: 163 | P10: =IFERROR(VLOOKUP(O10,Capacity!$A$3:$D$532,4,), "0") -> 42.725659 | Q10: =IFERROR(VLOOKUP(O10,Capacity!$A$3:$F$532,6,), "0") -> 0.4 | R10: =$P10 -> 42.725659 | S10: =$Q10 -> 0.4 | U10: 169 | V10: 3 | W10: 3 | X10: 1 | AB10: =($M10/$R10) -> 10.720588 | AC10: =($M10/$B10) -> 10.720588 | AD10: =($N10/$S10) -> 3.375 | AE10: =($N10/$C10) -> 3.375 | AG10: =$M10/($R10+$B10) -> 5.3602941
A11: 162 | B11: =IFERROR(VLOOKUP(A11,Capacity!$A$3:$D$532,4,), "0") -> 16.355916 | C11: =IFERROR(VLOOKUP(A11,Capacity!$A$3:$F$532,6,), "0") -> 0.175 | D11: 450 | E11: =IFERROR(VLOOKUP(D11,Capacity!$A$3:$D$532,4,), "0") -> 6.7347891 | F11: =IFERROR(VLOOKUP(D11,Capacity!$A$3:$F$532,6,), "0") -> 0.175 | H11: =IFERROR(VLOOKUP(G11,Capacity!$A$3:$D$532,4,), "0") -> 0 | I11: =IFERROR(VLOOKUP(G11,Capacity!$A$3:$F$532,6,), "0") -> 0 | K11: =IFERROR(VLOOKUP(J11,Capacity!$A$3:$D$532,4,), "0") -> 0 | L11: =IFERROR(VLOOKUP(J11,Capacity!$A$3:$F$532,6,), "0") -> 0 | M11: =$E11+$H11+$K11 -> 6.7347891 | N11: =$F11+$I11+$L11 -> 0.175 | O11: 163 | P11: =IFERROR(VLOOKUP(O11,Capacity!$A$3:$D$532,4,), "0") -> 42.725659 | Q11: =IFERROR(VLOOKUP(O11,Capacity!$A$3:$F$532,6,), "0") -> 0.4 | R11: =$P11 -> 42.725659 | S11: =$Q11 -> 0.4 | U11: 162 | V11: 2 | W11: 2 | X11: 1 | AB11: =($M11/$R11) -> 0.15762868 | AC11: =($M11/$B11) -> 0.41176471 | AD11: =($N11/$S11) -> 0.4375 | AE11: =($N11/$C11) -> 1 | AG11: =$M11/($R11+$B11) -> 0.11399136
A12: 148 | B12: =IFERROR(VLOOKUP(A12,Capacity!$A$3:$D$532,4,), "0") -> 23.876104 | C12: =IFERROR(VLOOKUP(A12,Capacity!$A$3:$F$532,6,), "0") -> 0.2 | D12: 147 | E12: =IFERROR(VLOOKUP(D12,Capacity!$A$3:$D$532,4,), "0") -> 23.876104 | F12: =IFERROR(VLOOKUP(D12,Capacity!$A$3:$F$532,6,), "0") -> 0.2 | H12: =IFERROR(VLOOKUP(G12,Capacity!$A$3:$D$532,4,), "0") -> 0 | I12: =IFERROR(VLOOKUP(G12,Capacity!$A$3:$F$532,6,), "0") -> 0 | K12: =IFERROR(VLOOKUP(J12,Capacity!$A$3:$D$532,4,), "0") -> 0 | L12: =IFERROR(VLOOKUP(J12,Capacity!$A$3:$F$532,6,), "0") -> 0 | M12: =$E12+$H12+$K12 -> 23.876104 | N12: =$F12+$I12+$L12 -> 0.2 | O12: 149 | P12: =IFERROR(VLOOKUP(O12,Capacity!$A$3:$D$532,4,), "0") -> 267.03537 | Q12: =IFERROR(VLOOKUP(O12,Capacity!$A$3:$F$532,6,), "0") -> 1 | R12: =$P12 -> 267.03537 | S12: =$Q12 -> 1 | U12: 148 | V12: 1 | W12: 1 | X12: 1 | AB12: =($M12/$R12) -> 0.089411765 | AC12: =($M12/$B12) -> 1 | AD12: =($N12/$S12) -> 0.2 | AE12: =($N12/$C12) -> 1 | AG12: =$M12/($R12+$B12) -> 0.082073434
A13: 144 | B13: =IFERROR(VLOOKUP(A13,Capacity!$A$3:$D$532,4,), "0") -> 267.03537 | C13: =IFERROR(VLOOKUP(A13,Capacity!$A$3:$F$532,6,), "0") -> 1 | D13: 143 | E13: =IFERROR(VLOOKUP(D13,Capacity!$A$3:$D$532,4,), "0") -> 17.799086 | F13: =IFERROR(VLOOKUP(D13,Capacity!$A$3:$F$532,6,), "0") -> 0.175 | G13: 137 | H13: =IFERROR(VLOOKUP(G13,Capacity!$A$3:$D$532,4,), "0") -> 267.03537 | I13: =IFERROR(VLOOKUP(G13,Capacity!$A$3:$F$532,6,), "0") -> 1 | K13: =IFERROR(VLOOKUP(J13,Capacity!$A$3:$D$532,4,), "0") -> 0 | L13: =IFERROR(VLOOKUP(J13,Capacity!$A$3:$F$532,6,), "0") -> 0 | M13: =$E13+$H13+$K13 -> 284.83446 | N13: =$F13+$I13+$L13 -> 1.175 | O13: 149 | P13: =IFERROR(VLOOKUP(O13,Capacity!$A$3:$D$532,4,), "0") -> 267.03537 | Q13: =IFERROR(VLOOKUP(O13,Capacity!$A$3:$F$532,6,), "0") -> 1 | R13: =$P13 -> 267.03537 | S13: =$Q13 -> 1 | U13: 144 | V13: 2 | W13: 2 | X13: 1 | AB13: =($M13/$R13) -> 1.0666544 | AC13: =($M13/$B13) -> 1.0666544 | AD13: =($N13/$S13) -> 1.175 | AE13: =($N13/$C13) -> 1.175 | AG13: =$M13/($R13+$B13) -> 0.53332721
A14: 151 | B14: =IFERROR(VLOOKUP(A14,Capacity!$A$3:$D$532,4,), "0") -> 25.132741 | C14: =IFERROR(VLOOKUP(A14,Capacity!$A$3:$F$532,6,), "0") -> 0.2 | D14: 150 | E14: =IFERROR(VLOOKUP(D14,Capacity!$A$3:$D$532,4,), "0") -> 19.242255 | F14: =IFERROR(VLOOKUP(D14,Capacity!$A$3:$F$532,6,), "0") -> 0.175 | H14: =IFERROR(VLOOKUP(G14,Capacity!$A$3:$D$532,4,), "0") -> 0 | I14: =IFERROR(VLOOKUP(G14,Capacity!$A$3:$F$532,6,), "0") -> 0 | K14: =IFERROR(VLOOKUP(J14,Capacity!$A$3:$D$532,4,), "0") -> 0 | L14: =IFERROR(VLOOKUP(J14,Capacity!$A$3:$F$532,6,), "0") -> 0 | M14: =$E14+$H14+$K14 -> 19.242255 | N14: =$F14+$I14+$L14 -> 0.175 | O14: 152 | P14: =IFERROR(VLOOKUP(O14,Capacity!$A$3:$D$532,4,), "0") -> 25.132741 | Q14: =IFERROR(VLOOKUP(O14,Capacity!$A$3:$F$532,6,), "0") -> 0.2 | R14: =$P14 -> 25.132741 | S14: =$Q14 -> 0.2 | U14: 151 | V14: 1 | W14: 1 | X14: 1 | AB14: =($M14/$R14) -> 0.765625 | AC14: =($M14/$B14) -> 0.765625 | AD14: =($N14/$S14) -> 0.875 | AE14: =($N14/$C14) -> 0.875 | AG14: =$M14/($R14+$B14) -> 0.3828125
A15: 154 | B15: =IFERROR(VLOOKUP(A15,Capacity!$A$3:$D$532,4,), "0") -> 388.77208 | C15: =IFERROR(VLOOKUP(A15,Capacity!$A$3:$F$532,6,), "0") -> 0.75 | D15: 87 | E15: =IFERROR(VLOOKUP(D15,Capacity!$A$3:$D$532,4,), "0") -> 388.77208 | F15: =IFERROR(VLOOKUP(D15,Capacity!$A$3:$F$532,6,), "0") -> 0.75 | H15: =IFERROR(VLOOKUP(G15,Capacity!$A$3:$D$532,4,), "0") -> 0 | I15: =IFERROR(VLOOKUP(G15,Capacity!$A$3:$F$532,6,), "0") -> 0 | K15: =IFERROR(VLOOKUP(J15,Capacity!$A$3:$D$532,4,), "0") -> 0 | L15: =IFERROR(VLOOKUP(J15,Capacity!$A$3:$F$532,6,), "0") -> 0 | M15: =$E15+$H15+$K15 -> 388.77208 | N15: =$F15+$I15+$L15 -> 0.75 | O15: 155 | P15: =IFERROR(VLOOKUP(O15,Capacity!$A$3:$D$532,4,), "0") -> 371.10063 | Q15: =IFERROR(VLOOKUP(O15,Capacity!$A$3:$F$532,6,), "0") -> 0.75 | R15: =$P15 -> 371.10063 | S15: =$Q15 -> 0.75 | U15: 154 | V15: 1 | W15: 1 | X15: 1 | AB15: =($M15/$R15) -> 1.047619 | AC15: =($M15/$B15) -> 1 | AD15: =($N15/$S15) -> 1 | AE15: =($N15/$C15) -> 1 | AG15: =$M15/($R15+$B15) -> 0.51162791
A16: 160 | B16: =IFERROR(VLOOKUP(A16,Capacity!$A$3:$D$532,4,), "0") -> 27.017696 | C16: =IFERROR(VLOOKUP(A16,Capacity!$A$3:$F$532,6,), "0") -> 0.2 | D16: 449 | E16: =IFERROR(VLOOKUP(D16,Capacity!$A$3:$D$532,4,), "0") -> 20.685424 | F16: =IFERROR(VLOOKUP(D16,Capacity!$A$3:$F$532,6,), "0") -> 0.175 | H16: =IFERROR(VLOOKUP(G16,Capacity!$A$3:$D$532,4,), "0") -> 0 | I16: =IFERROR(VLOOKUP(G16,Capacity!$A$3:$F$532,6,), "0") -> 0 | K16: =IFERROR(VLOOKUP(J16,Capacity!$A$3:$D$532,4,), "0") -> 0 | L16: =IFERROR(VLOOKUP(J16,Capacity!$A$3:$F$532,6,), "0") -> 0 | M16: =$E16+$H16+$K16 -> 20.685424 | N16: =$F16+$I16+$L16 -> 0.175 | O16: 161 | P16: =IFERROR(VLOOKUP(O16,Capacity!$A$3:$D$532,4,), "0") -> 17.649467 | Q16: =IFERROR(VLOOKUP(O16,Capacity!$A$3:$F$532,6,), "0") -> 0.265 | R16: =$P16 -> 17.649467 | S16: =$Q16 -> 0.265 | U16: 160 | V16: 2 | W16: 2 | X16: 1 | AB16: =($M16/$R16) -> 1.1720141 | AC16: =($M16/$B16) -> 0.765625 | AD16: =($N16/$S16) -> 0.66037736 | AE16: =($N16/$C16) -> 0.875 | AG16: =$M16/($R16+$B16) -> 0.46310135
A17: 450 | B17: =IFERROR(VLOOKUP(A17,Capacity!$A$3:$D$532,4,), "0") -> 6.7347891 | C17: =IFERROR(VLOOKUP(A17,Capacity!$A$3:$F$532,6,), "0") -> 0.175 | E17: =IFERROR(VLOOKUP(D17,Capacity!$A$3:$D$532,4,), "0") -> 0 | F17: =IFERROR(VLOOKUP(D17,Capacity!$A$3:$F$532,6,), "0") -> 0 | H17: =IFERROR(VLOOKUP(G17,Capacity!$A$3:$D$532,4,), "0") -> 0 | I17: =IFERROR(VLOOKUP(G17,Capacity!$A$3:$F$532,6,), "0") -> 0 | K17: =IFERROR(VLOOKUP(J17,Capacity!$A$3:$D$532,4,), "0") -> 0 | L17: =IFERROR(VLOOKUP(J17,Capacity!$A$3:$F$532,6,), "0") -> 0 | M17: =$E17+$H17+$K17 -> 0 | N17: =$F17+$I17+$L17 -> 0 | O17: 162 | P17: =IFERROR(VLOOKUP(O17,Capacity!$A$3:$D$532,4,), "0") -> 16.355916 | Q17: =IFERROR(VLOOKUP(O17,Capacity!$A$3:$F$532,6,), "0") -> 0.175 | R17: =$P17 -> 16.355916 | S17: =$Q17 -> 0.175 | U17: 450 | V17: 0 | W17: 0 | X17: 1 | AB17: =($M17/$R17) -> 0 | AC17: =($M17/$B17) -> 0 | AD17: =($N17/$S17) -> 0 | AE17: =($N17/$C17) -> 0 | AG17: =$M17/($R17+$B17) -> 0
A18: 177 | B18: =IFERROR(VLOOKUP(A18,Capacity!$A$3:$D$532,4,), "0") -> 282.74333 | C18: =IFERROR(VLOOKUP(A18,Capacity!$A$3:$F$532,6,), "0") -> 0.75 | D18: 176 | E18: =IFERROR(VLOOKUP(D18,Capacity!$A$3:$D$532,4,), "0") -> 19.242255 | F18: =IFERROR(VLOOKUP(D18,Capacity!$A$3:$F$532,6,), "0") -> 0.175 | G18: 183 | H18: =IFERROR(VLOOKUP(G18,Capacity!$A$3:$D$532,4,), "0") -> 40.212385 | I18: =IFERROR(VLOOKUP(G18,Capacity!$A$3:$F$532,6,), "0") -> 0.4 | K18: =IFERROR(VLOOKUP(J18,Capacity!$A$3:$D$532,4,), "0") -> 0 | L18: =IFERROR(VLOOKUP(J18,Capacity!$A$3:$F$532,6,), "0") -> 0 | M18: =$E18+$H18+$K18 -> 59.45464 | N18: =$F18+$I18+$L18 -> 0.575 | O18: 169 | P18: =IFERROR(VLOOKUP(O18,Capacity!$A$3:$D$532,4,), "0") -> 42.725659 | Q18: =IFERROR(VLOOKUP(O18,Capacity!$A$3:$F$532,6,), "0") -> 0.4 | R18: =$P18 -> 42.725659 | S18: =$Q18 -> 0.4 | U18: 177 | V18: 2 | W18: 2 | X18: 1 | AB18: =($M18/$R18) -> 1.3915441 | AC18: =($M18/$B18) -> 0.21027778 | AD18: =($N18/$S18) -> 1.4375 | AE18: =($N18/$C18) -> 0.76666667 | AG18: =$M18/($R18+$B18) -> 0.18267375
A19: 167 | B19: =IFERROR(VLOOKUP(A19,Capacity!$A$3:$D$532,4,), "0") -> 175.30087 | C19: =IFERROR(VLOOKUP(A19,Capacity!$A$3:$F$532,6,), "0") -> 0.6 | D19: 451 | E19: =IFERROR(VLOOKUP(D19,Capacity!$A$3:$D$532,4,), "0") -> 8.6590146 | F19: =IFERROR(VLOOKUP(D19,Capacity!$A$3:$F$532,6,), "0") -> 0.175 | G19: 166 | H19: =IFERROR(VLOOKUP(G19,Capacity!$A$3:$D$532,4,), "0") -> 47.432943 | I19: =IFERROR(VLOOKUP(G19,Capacity!$A$3:$F$532,6,), "0") -> 0.265 | K19: =IFERROR(VLOOKUP(J19,Capacity!$A$3:$D$532,4,), "0") -> 0 | L19: =IFERROR(VLOOKUP(J19,Capacity!$A$3:$F$532,6,), "0") -> 0 | M19: =$E19+$H19+$K19 -> 56.091958 | N19: =$F19+$I19+$L19 -> 0.44 | O19: 169 | P19: =IFERROR(VLOOKUP(O19,Capacity!$A$3:$D$532,4,), "0") -> 42.725659 | Q19: =IFERROR(VLOOKUP(O19,Capacity!$A$3:$F$532,6,), "0") -> 0.4 | R19: =$P19 -> 42.725659 | S19: =$Q19 -> 0.4 | U19: 167 | V19: 3 | W19: 3 | X19: 1 | AB19: =($M19/$R19) -> 1.3128401 | AC19: =($M19/$B19) -> 0.31997536 | AD19: =($N19/$S19) -> 1.1 | AE19: =($N19/$C19) -> 0.73333333 | AG19: =$M19/($R19+$B19) -> 0.25727125
A20: 143 | B20: =IFERROR(VLOOKUP(A20,Capacity!$A$3:$D$532,4,), "0") -> 17.799086 | C20: =IFERROR(VLOOKUP(A20,Capacity!$A$3:$F$532,6,), "0") -> 0.175 | D20: 142 | E20: =IFERROR(VLOOKUP(D20,Capacity!$A$3:$D$532,4,), "0") -> 17.799086 | F20: =IFERROR(VLOOKUP(D20,Capacity!$A$3:$F$532,6,), "0") -> 0.175 | H20: =IFERROR(VLOOKUP(G20,Capacity!$A$3:$D$532,4,), "0") -> 0 | I20: =IFERROR(VLOOKUP(G20,Capacity!$A$3:$F$532,6,), "0") -> 0 | K20: =IFERROR(VLOOKUP(J20,Capacity!$A$3:$D$532,4,), "0") -> 0 | L20: =IFERROR(VLOOKUP(J20,Capacity!$A$3:$F$532,6,), "0") -> 0 | M20: =$E20+$H20+$K20 -> 17.799086 | N20: =$F20+$I20+$L20 -> 0.175 | O20: 144 | P20: =IFERROR(VLOOKUP(O20,Capacity!$A$3:$D$532,4,), "0") -> 267.03537 | Q20: =IFERROR(VLOOKUP(O20,Capacity!$A$3:$F$532,6,), "0") -> 1 | R20: =$P20 -> 267.03537 | S20: =$Q20 -> 1 | U20: 143 | V20: 1 | W20: 1 | X20: 1 | AB20: =($M20/$R20) -> 0.066654412 | AC20: =($M20/$B20) -> 1 | AD20: =($N20/$S20) -> 0.175 | AE20: =($N20/$C20) -> 1 | AG20: =$M20/($R20+$B20) -> 0.062489229
A21: 137 | B21: =IFERROR(VLOOKUP(A21,Capacity!$A$3:$D$532,4,), "0") -> 267.03537 | C21: =IFERROR(VLOOKUP(A21,Capacity!$A$3:$F$532,6,), "0") -> 1 | D21: 138 | E21: =IFERROR(VLOOKUP(D21,Capacity!$A$3:$D$532,4,), "0") -> 48.066367 | F21: =IFERROR(VLOOKUP(D21,Capacity!$A$3:$F$532,6,), "0") -> 0.3 | G21: 136 | H21: =IFERROR(VLOOKUP(G21,Capacity!$A$3:$D$532,4,), "0") -> 150.2074 | I21: =IFERROR(VLOOKUP(G21,Capacity!$A$3:$F$532,6,), "0") -> 0.75 | K21: =IFERROR(VLOOKUP(J21,Capacity!$A$3:$D$532,4,), "0") -> 0 | L21: =IFERROR(VLOOKUP(J21,Capacity!$A$3:$F$532,6,), "0") -> 0 | M21: =$E21+$H21+$K21 -> 198.27376 | N21: =$F21+$I21+$L21 -> 1.05 | O21: 144 | P21: =IFERROR(VLOOKUP(O21,Capacity!$A$3:$D$532,4,), "0") -> 267.03537 | Q21: =IFERROR(VLOOKUP(O21,Capacity!$A$3:$F$532,6,), "0") -> 1 | R21: =$P21 -> 267.03537 | S21: =$Q21 -> 1 | U21: 137 | V21: 3 | W21: 3 | X21: 1 | AB21: =($M21/$R21) -> 0.7425 | AC21: =($M21/$B21) -> 0.7425 | AD21: =($N21/$S21) -> 1.05 | AE21: =($N21/$C21) -> 1.05 | AG21: =$M21/($R21+$B21) -> 0.37125
A22: 147 | B22: =IFERROR(VLOOKUP(A22,Capacity!$A$3:$D$532,4,), "0") -> 23.876104 | C22: =IFERROR(VLOOKUP(A22,Capacity!$A$3:$F$532,6,), "0") -> 0.2 | D22: 145 | E22: =IFERROR(VLOOKUP(D22,Capacity!$A$3:$D$532,4,), "0") -> 23.876104 | F22: =IFERROR(VLOOKUP(D22,Capacity!$A$3:$F$532,6,), "0") -> 0.2 | H22: =IFERROR(VLOOKUP(G22,Capacity!$A$3:$D$532,4,), "0") -> 0 | I22: =IFERROR(VLOOKUP(G22,Capacity!$A$3:$F$532,6,), "0") -> 0 | K22: =IFERROR(VLOOKUP(J22,Capacity!$A$3:$D$532,4,), "0") -> 0 | L22: =IFERROR(VLOOKUP(J22,Capacity!$A$3:$F$532,6,), "0") -> 0 | M22: =$E22+$H22+$K22 -> 23.876104 | N22: =$F22+$I22+$L22 -> 0.2 | O22: 148 | P22: =IFERROR(VLOOKUP(O22,Capacity!$A$3:$D$532,4,), "0") -> 23.876104 | Q22: =IFERROR(VLOOKUP(O22,Capacity!$A$3:$F$532,6,), "0") -> 0.2 | R22: =$P22 -> 23.876104 | S22: =$Q22 -> 0.2 | U22: 147 | V22: 2 | W22: 2 | X22: 1 | AB22: =($M22/$R22) -> 1 | AC22: =($M22/$B22) -> 1 | AD22: =($N22/$S22) -> 1 | AE22: =($N22/$C22) -> 1 | AG22: =$M22/($R22+$B22) -> 0.5
A23: 150 | B23: =IFERROR(VLOOKUP(A23,Capacity!$A$3:$D$532,4,), "0") -> 19.242255 | C23: =IFERROR(VLOOKUP(A23,Capacity!$A$3:$F$532,6,), "0") -> 0.175 | D23: 446 | E23: =IFERROR(VLOOKUP(D23,Capacity!$A$3:$D$532,4,), "0") -> 40.212385 | F23: =IFERROR(VLOOKUP(D23,Capacity!$A$3:$F$532,6,), "0") -> 0.4 | G23: 88 | H23: =IFERROR(VLOOKUP(G23,Capacity!$A$3:$D$532,4,), "0") -> 172.78759 | I23: =IFERROR(VLOOKUP(G23,Capacity!$A$3:$F$532,6,), "0") -> 0.5 | K23: =IFERROR(VLOOKUP(J23,Capacity!$A$3:$D$532,4,), "0") -> 0 | L23: =IFERROR(VLOOKUP(J23,Capacity!$A$3:$F$532,6,), "0") -> 0 | M23: =$E23+$H23+$K23 -> 212.99998 | N23: =$F23+$I23+$L23 -> 0.9 | O23: 151 | P23: =IFERROR(VLOOKUP(O23,Capacity!$A$3:$D$532,4,), "0") -> 25.132741 | Q23: =IFERROR(VLOOKUP(O23,Capacity!$A$3:$F$532,6,), "0") -> 0.2 | R23: =$P23 -> 25.132741 | S23: =$Q23 -> 0.2 | U23: 150 | V23: 3 | W23: 3 | X23: 1 | AB23: =($M23/$R23) -> 8.475 | AC23: =($M23/$B23) -> 11.069388 | AD23: =($N23/$S23) -> 4.5 | AE23: =($N23/$C23) -> 5.1428571 | AG23: =$M23/($R23+$B23) -> 4.8
A24: 448 | B24: =IFERROR(VLOOKUP(A24,Capacity!$A$3:$D$532,4,), "0") -> 7.6969019 | C24: =IFERROR(VLOOKUP(A24,Capacity!$A$3:$F$532,6,), "0") -> 0.175 | E24: =IFERROR(VLOOKUP(D24,Capacity!$A$3:$D$532,4,), "0") -> 0 | F24: =IFERROR(VLOOKUP(D24,Capacity!$A$3:$F$532,6,), "0") -> 0 | H24: =IFERROR(VLOOKUP(G24,Capacity!$A$3:$D$532,4,), "0") -> 0 | I24: =IFERROR(VLOOKUP(G24,Capacity!$A$3:$F$532,6,), "0") -> 0 | K24: =IFERROR(VLOOKUP(J24,Capacity!$A$3:$D$532,4,), "0") -> 0 | L24: =IFERROR(VLOOKUP(J24,Capacity!$A$3:$F$532,6,), "0") -> 0 | M24: =$E24+$H24+$K24 -> 0 | N24: =$F24+$I24+$L24 -> 0 | O24: 154 | P24: =IFERROR(VLOOKUP(O24,Capacity!$A$3:$D$532,4,), "0") -> 388.77208 | Q24: =IFERROR(VLOOKUP(O24,Capacity!$A$3:$F$532,6,), "0") -> 0.75 | R24: =$P24 -> 388.77208 | S24: =$Q24 -> 0.75 | U24: 448 | V24: 0 | W24: 0 | X24: 1 | AB24: =($M24/$R24) -> 0 | AC24: =($M24/$B24) -> 0 | AD24: =($N24/$S24) -> 0 | AE24: =($N24/$C24) -> 0 | AG24: =$M24/($R24+$B24) -> 0
A25: 159 | B25: =IFERROR(VLOOKUP(A25,Capacity!$A$3:$D$532,4,), "0") -> 22.619467 | C25: =IFERROR(VLOOKUP(A25,Capacity!$A$3:$F$532,6,), "0") -> 0.3 | D25: 419 | E25: =IFERROR(VLOOKUP(D25,Capacity!$A$3:$D$532,4,), "0") -> 21.16648 | F25: =IFERROR(VLOOKUP(D25,Capacity!$A$3:$F$532,6,), "0") -> 0.175 | G25: 164 | H25: =IFERROR(VLOOKUP(G25,Capacity!$A$3:$D$532,4,), "0") -> 22.619467 | I25: =IFERROR(VLOOKUP(G25,Capacity!$A$3:$F$532,6,), "0") -> 0.3 | K25: =IFERROR(VLOOKUP(J25,Capacity!$A$3:$D$532,4,), "0") -> 0 | L25: =IFERROR(VLOOKUP(J25,Capacity!$A$3:$F$532,6,), "0") -> 0 | M25: =$E25+$H25+$K25 -> 43.785947 | N25: =$F25+$I25+$L25 -> 0.475 | O25: 154 | P25: =IFERROR(VLOOKUP(O25,Capacity!$A$3:$D$532,4,), "0") -> 388.77208 | Q25: =IFERROR(VLOOKUP(O25,Capacity!$A$3:$F$532,6,), "0") -> 0.75 | R25: =$P25 -> 388.77208 | S25: =$Q25 -> 0.75 | U25: 159 | V25: 2 | W25: 2 | X25: 1 | AB25: =($M25/$R25) -> 0.11262626 | AC25: =($M25/$B25) -> 1.9357639 | AD25: =($N25/$S25) -> 0.63333333 | AE25: =($N25/$C25) -> 1.5833333 | AG25: =$M25/($R25+$B25) -> 0.10643375
A26: 87 | B26: =IFERROR(VLOOKUP(A26,Capacity!$A$3:$D$532,4,), "0") -> 388.77208 | C26: =IFERROR(VLOOKUP(A26,Capacity!$A$3:$F$532,6,), "0") -> 0.75 | D26: 48 | E26: =IFERROR(VLOOKUP(D26,Capacity!$A$3:$D$532,4,), "0") -> 397.60781 | F26: =IFERROR(VLOOKUP(D26,Capacity!$A$3:$F$532,6,), "0") -> 0.75 | G26: 86 | H26: =IFERROR(VLOOKUP(G26,Capacity!$A$3:$D$532,4,), "0") -> 90.477867 | I26: =IFERROR(VLOOKUP(G26,Capacity!$A$3:$F$532,6,), "0") -> 0.6 | K26: =IFERROR(VLOOKUP(J26,Capacity!$A$3:$D$532,4,), "0") -> 0 | L26: =IFERROR(VLOOKUP(J26,Capacity!$A$3:$F$532,6,), "0") -> 0 | M26: =$E26+$H26+$K26 -> 488.08568 | N26: =$F26+$I26+$L26 -> 1.35 | O26: 154 | P26: =IFERROR(VLOOKUP(O26,Capacity!$A$3:$D$532,4,), "0") -> 388.77208 | Q26: =IFERROR(VLOOKUP(O26,Capacity!$A$3:$F$532,6,), "0") -> 0.75 | R26: =$P26 -> 388.77208 | S26: =$Q26 -> 0.75 | U26: 87 | V26: 3 | W26: 3 | X26: 1 | AB26: =($M26/$R26) -> 1.2554545 | AC26: =($M26/$B26) -> 1.2554545 | AD26: =($N26/$S26) -> 1.8 | AE26: =($N26/$C26) -> 1.8 | AG26: =$M26/($R26+$B26) -> 0.62772727
A27: 449 | B27: =IFERROR(VLOOKUP(A27,Capacity!$A$3:$D$532,4,), "0") -> 20.685424 | C27: =IFERROR(VLOOKUP(A27,Capacity!$A$3:$F$532,6,), "0") -> 0.175 | E27: =IFERROR(VLOOKUP(D27,Capacity!$A$3:$D$532,4,), "0") -> 0 | F27: =IFERROR(VLOOKUP(D27,Capacity!$A$3:$F$532,6,), "0") -> 0 | H27: =IFERROR(VLOOKUP(G27,Capacity!$A$3:$D$532,4,), "0") -> 0 | I27: =IFERROR(VLOOKUP(G27,Capacity!$A$3:$F$532,6,), "0") -> 0 | K27: =IFERROR(VLOOKUP(J27,Capacity!$A$3:$D$532,4,), "0") -> 0 | L27: =IFERROR(VLOOKUP(J27,Capacity!$A$3:$F$532,6,), "0") -> 0 | M27: =$E27+$H27+$K27 -> 0 | N27: =$F27+$I27+$L27 -> 0 | O27: 160 | P27: =IFERROR(VLOOKUP(O27,Capacity!$A$3:$D$532,4,), "0") -> 27.017696 | Q27: =IFERROR(VLOOKUP(O27,Capacity!$A$3:$F$532,6,), "0") -> 0.2 | R27: =$P27 -> 27.017696 | S27: =$Q27 -> 0.2 | U27: 449 | V27: 0 | W27: 0 | X27: 1 | AB27: =($M27/$R27) -> 0 | AC27: =($M27/$B27) -> 0 | AD27: =($N27/$S27) -> 0 | AE27: =($N27/$C27) -> 0 | AG27: =$M27/($R27+$B27) -> 0
A28: 451 | B28: =IFERROR(VLOOKUP(A28,Capacity!$A$3:$D$532,4,), "0") -> 8.6590146 | C28: =IFERROR(VLOOKUP(A28,Capacity!$A$3:$F$532,6,), "0") -> 0.175 | E28: =IFERROR(VLOOKUP(D28,Capacity!$A$3:$D$532,4,), "0") -> 0 | F28: =IFERROR(VLOOKUP(D28,Capacity!$A$3:$F$532,6,), "0") -> 0 | H28: =IFERROR(VLOOKUP(G28,Capacity!$A$3:$D$532,4,), "0") -> 0 | I28: =IFERROR(VLOOKUP(G28,Capacity!$A$3:$F$532,6,), "0") -> 0 | K28: =IFERROR(VLOOKUP(J28,Capacity!$A$3:$D$532,4,), "0") -> 0 | L28: =IFERROR(VLOOKUP(J28,Capacity!$A$3:$F$532,6,), "0") -> 0 | M28: =$E28+$H28+$K28 -> 0 | N28: =$F28+$I28+$L28 -> 0 | O28: 167 | P28: =IFERROR(VLOOKUP(O28,Capacity!$A$3:$D$532,4,), "0") -> 175.30087 | Q28: =IFERROR(VLOOKUP(O28,Capacity!$A$3:$F$532,6,), "0") -> 0.6 | R28: =$P28 -> 175.30087 | S28: =$Q28 -> 0.6 | U28: 451 | V28: 0 | W28: 0 | X28: 1 | AB28: =($M28/$R28) -> 0 | AC28: =($M28/$B28) -> 0 | AD28: =($N28/$S28) -> 0 | AE28: =($N28/$C28) -> 0 | AG28: =$M28/($R28+$B28) -> 0
A29: 166 | B29: =IFERROR(VLOOKUP(A29,Capacity!$A$3:$D$532,4,), "0") -> 47.432943 | C29: =IFERROR(VLOOKUP(A29,Capacity!$A$3:$F$532,6,), "0") -> 0.265 | D29: 165 | E29: =IFERROR(VLOOKUP(D29,Capacity!$A$3:$D$532,4,), "0") -> 15.87486 | F29: =IFERROR(VLOOKUP(D29,Capacity!$A$3:$F$532,6,), "0") -> 0.175 | G29: 172 | H29: =IFERROR(VLOOKUP(G29,Capacity!$A$3:$D$532,4,), "0") -> 22.619467 | I29: =IFERROR(VLOOKUP(G29,Capacity!$A$3:$F$532,6,), "0") -> 0.3 | K29: =IFERROR(VLOOKUP(J29,Capacity!$A$3:$D$532,4,), "0") -> 0 | L29: =IFERROR(VLOOKUP(J29,Capacity!$A$3:$F$532,6,), "0") -> 0 | M29: =$E29+$H29+$K29 -> 38.494327 | N29: =$F29+$I29+$L29 -> 0.475 | O29: 167 | P29: =IFERROR(VLOOKUP(O29,Capacity!$A$3:$D$532,4,), "0") -> 175.30087 | Q29: =IFERROR(VLOOKUP(O29,Capacity!$A$3:$F$532,6,), "0") -> 0.6 | R29: =$P29 -> 175.30087 | S29: =$Q29 -> 0.6 | U29: 166 | V29: 2 | W29: 2 | X29: 1 | AB29: =($M29/$R29) -> 0.21959005 | AC29: =($M29/$B29) -> 0.81155257 | AD29: =($N29/$S29) -> 0.79166667 | AE29: =($N29/$C29) -> 1.7924528 | AG29: =$M29/($R29+$B29) -> 0.1728266
A30: 183 | B30: =IFERROR(VLOOKUP(A30,Capacity!$A$3:$D$532,4,), "0") -> 40.212385 | C30: =IFERROR(VLOOKUP(A30,Capacity!$A$3:$F$532,6,), "0") -> 0.4 | D30: 188 | E30: =IFERROR(VLOOKUP(D30,Capacity!$A$3:$D$532,4,), "0") -> 40.212385 | F30: =IFERROR(VLOOKUP(D30,Capacity!$A$3:$F$532,6,), "0") -> 0.4 | G30: 182 | H30: =IFERROR(VLOOKUP(G30,Capacity!$A$3:$D$532,4,), "0") -> 19.242255 | I30: =IFERROR(VLOOKUP(G30,Capacity!$A$3:$F$532,6,), "0") -> 0.175 | K30: =IFERROR(VLOOKUP(J30,Capacity!$A$3:$D$532,4,), "0") -> 0 | L30: =IFERROR(VLOOKUP(J30,Capacity!$A$3:$F$532,6,), "0") -> 0 | M30: =$E30+$H30+$K30 -> 59.45464 | N30: =$F30+$I30+$L30 -> 0.575 | O30: 177 | P30: =IFERROR(VLOOKUP(O30,Capacity!$A$3:$D$532,4,), "0") -> 282.74333 | Q30: =IFERROR(VLOOKUP(O30,Capacity!$A$3:$F$532,6,), "0") -> 0.75 | R30: =$P30 -> 282.74333 | S30: =$Q30 -> 0.75 | U30: 183 | V30: 3 | W30: 3 | X30: 1 | AB30: =($M30/$R30) -> 0.21027778 | AC30: =($M30/$B30) -> 1.4785156 | AD30: =($N30/$S30) -> 0.76666667 | AE30: =($N30/$C30) -> 1.4375 | AG30: =$M30/($R30+$B30) -> 0.18409533
A31: 176 | B31: =IFERROR(VLOOKUP(A31,Capacity!$A$3:$D$532,4,), "0") -> 19.242255 | C31: =IFERROR(VLOOKUP(A31,Capacity!$A$3:$F$532,6,), "0") -> 0.175 | D31: 456 | E31: =IFERROR(VLOOKUP(D31,Capacity!$A$3:$D$532,4,), "0") -> 19.242255 | F31: =IFERROR(VLOOKUP(D31,Capacity!$A$3:$F$532,6,), "0") -> 0.175 | H31: =IFERROR(VLOOKUP(G31,Capacity!$A$3:$D$532,4,), "0") -> 0 | I31: =IFERROR(VLOOKUP(G31,Capacity!$A$3:$F$532,6,), "0") -> 0 | K31: =IFERROR(VLOOKUP(J31,Capacity!$A$3:$D$532,4,), "0") -> 0 | L31: =IFERROR(VLOOKUP(J31,Capacity!$A$3:$F$532,6,), "0") -> 0 | M31: =$E31+$H31+$K31 -> 19.242255 | N31: =$F31+$I31+$L31 -> 0.175 | O31: 177 | P31: =IFERROR(VLOOKUP(O31,Capacity!$A$3:$D$532,4,), "0") -> 282.74333 | Q31: =IFERROR(VLOOKUP(O31,Capacity!$A$3:$F$532,6,), "0") -> 0.75 | R31: =$P31 -> 282.74333 | S31: =$Q31 -> 0.75 | U31: 176 | V31: 2 | W31: 2 | X31: 1 | AB31: =($M31/$R31) -> 0.068055556 | AC31: =($M31/$B31) -> 1 | AD31: =($N31/$S31) -> 0.23333333 | AE31: =($N31/$C31) -> 1 | AG31: =$M31/($R31+$B31) -> 0.063719116
A32: 138 | B32: =IFERROR(VLOOKUP(A32,Capacity!$A$3:$D$532,4,), "0") -> 48.066367 | C32: =IFERROR(VLOOKUP(A32,Capacity!$A$3:$F$532,6,), "0") -> 0.3 | D32: 139 | E32: =IFERROR(VLOOKUP(D32,Capacity!$A$3:$D$532,4,), "0") -> 48.066367 | F32: =IFERROR(VLOOKUP(D32,Capacity!$A$3:$F$532,6,), "0") -> 0.3 | H32: =IFERROR(VLOOKUP(G32,Capacity!$A$3:$D$532,4,), "0") -> 0 | I32: =IFERROR(VLOOKUP(G32,Capacity!$A$3:$F$532,6,), "0") -> 0 | K32: =IFERROR(VLOOKUP(J32,Capacity!$A$3:$D$532,4,), "0") -> 0 | L32: =IFERROR(VLOOKUP(J32,Capacity!$A$3:$F$532,6,), "0") -> 0 | M32: =$E32+$H32+$K32 -> 48.066367 | N32: =$F32+$I32+$L32 -> 0.3 | O32: 137 | P32: =IFERROR(VLOOKUP(O32,Capacity!$A$3:$D$532,4,), "0") -> 267.03537 | Q32: =IFERROR(VLOOKUP(O32,Capacity!$A$3:$F$532,6,), "0") -> 1 | R32: =$P32 -> 267.03537 | S32: =$Q32 -> 1 | U32: 138 | V32: 2 | W32: 2 | X32: 1 | AB32: =($M32/$R32) -> 0.18 | AC32: =($M32/$B32) -> 1 | AD32: =($N32/$S32) -> 0.3 | AE32: =($N32/$C32) -> 1 | AG32: =$M32/($R32+$B32) -> 0.15254237
A33: 136 | B33: =IFERROR(VLOOKUP(A33,Capacity!$A$3:$D$532,4,), "0") -> 150.2074 | C33: =IFERROR(VLOOKUP(A33,Capacity!$A$3:$F$532,6,), "0") -> 0.75 | D33: 134 | E33: =IFERROR(VLOOKUP(D33,Capacity!$A$3:$D$532,4,), "0") -> 273.9076 | F33: =IFERROR(VLOOKUP(D33,Capacity!$A$3:$F$532,6,), "0") -> 0.75 | G33: 128 | H33: =IFERROR(VLOOKUP(G33,Capacity!$A$3:$D$532,4,), "0") -> 31.101767 | I33: =IFERROR(VLOOKUP(G33,Capacity!$A$3:$F$532,6,), "0") -> 0.3 | J33: 276 | K33: =IFERROR(VLOOKUP(J33,Capacity!$A$3:$D$532,4,), "0") -> 24.052818 | L33: =IFERROR(VLOOKUP(J33,Capacity!$A$3:$F$532,6,), "0") -> 0.175 | M33: =$E33+$H33+$K33 -> 329.06219 | N33: =$F33+$I33+$L33 -> 1.225 | O33: 137 | P33: =IFERROR(VLOOKUP(O33,Capacity!$A$3:$D$532,4,), "0") -> 267.03537 | Q33: =IFERROR(VLOOKUP(O33,Capacity!$A$3:$F$532,6,), "0") -> 1 | R33: =$P33 -> 267.03537 | S33: =$Q33 -> 1 | U33: 136 | V33: 3 | W33: 3 | X33: 1 | AB33: =($M33/$R33) -> 1.2322794 | AC33: =($M33/$B33) -> 2.190719 | AD33: =($N33/$S33) -> 1.225 | AE33: =($N33/$C33) -> 1.6333333 | AG33: =$M33/($R33+$B33) -> 0.78865882
A34: 142 | B34: =IFERROR(VLOOKUP(A34,Capacity!$A$3:$D$532,4,), "0") -> 17.799086 | C34: =IFERROR(VLOOKUP(A34,Capacity!$A$3:$F$532,6,), "0") -> 0.175 | D34: 141 | E34: =IFERROR(VLOOKUP(D34,Capacity!$A$3:$D$532,4,), "0") -> 17.799086 | F34: =IFERROR(VLOOKUP(D34,Capacity!$A$3:$F$532,6,), "0") -> 0.175 | H34: =IFERROR(VLOOKUP(G34,Capacity!$A$3:$D$532,4,), "0") -> 0 | I34: =IFERROR(VLOOKUP(G34,Capacity!$A$3:$F$532,6,), "0") -> 0 | K34: =IFERROR(VLOOKUP(J34,Capacity!$A$3:$D$532,4,), "0") -> 0 | L34: =IFERROR(VLOOKUP(J34,Capacity!$A$3:$F$532,6,), "0") -> 0 | M34: =$E34+$H34+$K34 -> 17.799086 | N34: =$F34+$I34+$L34 -> 0.175 | O34: 143 | P34: =IFERROR(VLOOKUP(O34,Capacity!$A$3:$D$532,4,), "0") -> 17.799086 | Q34: =IFERROR(VLOOKUP(O34,Capacity!$A$3:$F$532,6,), "0") -> 0.175 | R34: =$P34 -> 17.799086 | S34: =$Q34 -> 0.175 | U34: 142 | V34: 2 | W34: 2 | X34: 1 | AB34: =($M34/$R34) -> 1 | AC34: =($M34/$B34) -> 1 | AD34: =($N34/$S34) -> 1 | AE34: =($N34/$C34) -> 1 | AG34: =$M34/($R34+$B34) -> 0.5
A35: 145 | B35: =IFERROR(VLOOKUP(A35,Capacity!$A$3:$D$532,4,), "0") -> 23.876104 | C35: =IFERROR(VLOOKUP(A35,Capacity!$A$3:$F$532,6,), "0") -> 0.2 | D35: 445 | E35: =IFERROR(VLOOKUP(D35,Capacity!$A$3:$D$532,4,), "0") -> 7.6969019 | F35: =IFERROR(VLOOKUP(D35,Capacity!$A$3:$F$532,6,), "0") -> 0.175 | G35: 89 | H35: =IFERROR(VLOOKUP(G35,Capacity!$A$3:$D$532,4,), "0") -> 27.646015 | I35: =IFERROR(VLOOKUP(G35,Capacity!$A$3:$F$532,6,), "0") -> 0.2 | K35: =IFERROR(VLOOKUP(J35,Capacity!$A$3:$D$532,4,), "0") -> 0 | L35: =IFERROR(VLOOKUP(J35,Capacity!$A$3:$F$532,6,), "0") -> 0 | M35: =$E35+$H35+$K35 -> 35.342917 | N35: =$F35+$I35+$L35 -> 0.375 | O35: 147 | P35: =IFERROR(VLOOKUP(O35,Capacity!$A$3:$D$532,4,), "0") -> 23.876104 | Q35: =IFERROR(VLOOKUP(O35,Capacity!$A$3:$F$532,6,), "0") -> 0.2 | R35: =$P35 -> 23.876104 | S35: =$Q35 -> 0.2 | U35: 145 | V35: 3 | W35: 3 | X35: 1 | AB35: =($M35/$R35) -> 1.4802632 | AC35: =($M35/$B35) -> 1.4802632 | AD35: =($N35/$S35) -> 1.875 | AE35: =($N35/$C35) -> 1.875 | AG35: =$M35/($R35+$B35) -> 0.74013158
A36: 446 | B36: =IFERROR(VLOOKUP(A36,Capacity!$A$3:$D$532,4,), "0") -> 40.212385 | C36: =IFERROR(VLOOKUP(A36,Capacity!$A$3:$F$532,6,), "0") -> 0.4 | E36: =IFERROR(VLOOKUP(D36,Capacity!$A$3:$D$532,4,), "0") -> 0 | F36: =IFERROR(VLOOKUP(D36,Capacity!$A$3:$F$532,6,), "0") -> 0 | H36: =IFERROR(VLOOKUP(G36,Capacity!$A$3:$D$532,4,), "0") -> 0 | I36: =IFERROR(VLOOKUP(G36,Capacity!$A$3:$F$532,6,), "0") -> 0 | K36: =IFERROR(VLOOKUP(J36,Capacity!$A$3:$D$532,4,), "0") -> 0 | L36: =IFERROR(VLOOKUP(J36,Capacity!$A$3:$F$532,6,), "0") -> 0 | M36: =$E36+$H36+$K36 -> 0 | N36: =$F36+$I36+$L36 -> 0 | O36: 150 | P36: =IFERROR(VLOOKUP(O36,Capacity!$A$3:$D$532,4,), "0") -> 19.242255 | Q36: =IFERROR(VLOOKUP(O36,Capacity!$A$3:$F$532,6,), "0") -> 0.175 | R36: =$P36 -> 19.242255 | S36: =$Q36 -> 0.175 | U36: 446 | V36: 0 | W36: 0 | X36: 1 | AB36: =($M36/$R36) -> 0 | AC36: =($M36/$B36) -> 0 | AD36: =($N36/$S36) -> 0 | AE36: =($N36/$C36) -> 0 | AG36: =$M36/($R36+$B36) -> 0
A37: 88 | B37: =IFERROR(VLOOKUP(A37,Capacity!$A$3:$D$532,4,), "0") -> 172.78759 | C37: =IFERROR(VLOOKUP(A37,Capacity!$A$3:$F$532,6,), "0") -> 0.5 | D37: 420 | E37: =IFERROR(VLOOKUP(D37,Capacity!$A$3:$D$532,4,), "0") -> 7.6969019 | F37: =IFERROR(VLOOKUP(D37,Capacity!$A$3:$F$532,6,), "0") -> 0.175 | G37: 49 | H37: =IFERROR(VLOOKUP(G37,Capacity!$A$3:$D$532,4,), "0") -> 21.647537 | I37: =IFERROR(VLOOKUP(G37,Capacity!$A$3:$F$532,6,), "0") -> 0.175 | K37: =IFERROR(VLOOKUP(J37,Capacity!$A$3:$D$532,4,), "0") -> 0 | L37: =IFERROR(VLOOKUP(J37,Capacity!$A$3:$F$532,6,), "0") -> 0 | M37: =$E37+$H37+$K37 -> 29.344438 | N37: =$F37+$I37+$L37 -> 0.35 | O37: 150 | P37: =IFERROR(VLOOKUP(O37,Capacity!$A$3:$D$532,4,), "0") -> 19.242255 | Q37: =IFERROR(VLOOKUP(O37,Capacity!$A$3:$F$532,6,), "0") -> 0.175 | R37: =$P37 -> 19.242255 | S37: =$Q37 -> 0.175 | U37: 88 | V37: 2 | W37: 2 | X37: 1 | AB37: =($M37/$R37) -> 1.525 | AC37: =($M37/$B37) -> 0.16982955 | AD37: =($N37/$S37) -> 2 | AE37: =($N37/$C37) -> 0.7 | AG37: =$M37/($R37+$B37) -> 0.15281186
A38: 86 | B38: =IFERROR(VLOOKUP(A38,Capacity!$A$3:$D$532,4,), "0") -> 90.477867 | C38: =IFERROR(VLOOKUP(A38,Capacity!$A$3:$F$532,6,), "0") -> 0.6 | D38: 85 | E38: =IFERROR(VLOOKUP(D38,Capacity!$A$3:$D$532,4,), "0") -> 90.477867 | F38: =IFERROR(VLOOKUP(D38,Capacity!$A$3:$F$532,6,), "0") -> 0.6 | H38: =IFERROR(VLOOKUP(G38,Capacity!$A$3:$D$532,4,), "0") -> 0 | I38: =IFERROR(VLOOKUP(G38,Capacity!$A$3:$F$532,6,), "0") -> 0 | K38: =IFERROR(VLOOKUP(J38,Capacity!$A$3:$D$532,4,), "0") -> 0 | L38: =IFERROR(VLOOKUP(J38,Capacity!$A$3:$F$532,6,), "0") -> 0 | M38: =$E38+$H38+$K38 -> 90.477867 | N38: =$F38+$I38+$L38 -> 0.6 | O38: 87 | P38: =IFERROR(VLOOKUP(O38,Capacity!$A$3:$D$532,4,), "0") -> 388.77208 | Q38: =IFERROR(VLOOKUP(O38,Capacity!$A$3:$F$532,6,), "0") -> 0.75 | R38: =$P38 -> 388.77208 | S38: =$Q38 -> 0.75 | U38: 86 | V38: 2 | W38: 2 | X38: 1 | AB38: =($M38/$R38) -> 0.23272727 | AC38: =($M38/$B38) -> 1 | AD38: =($N38/$S38) -> 0.8 | AE38: =($N38/$C38) -> 1 | AG38: =$M38/($R38+$B38) -> 0.18879056
A39: 48 | B39: =IFERROR(VLOOKUP(A39,Capacity!$A$3:$D$532,4,), "0") -> 397.60781 | C39: =IFERROR(VLOOKUP(A39,Capacity!$A$3:$F$532,6,), "0") -> 0.75 | D39: 23 | E39: =IFERROR(VLOOKUP(D39,Capacity!$A$3:$D$532,4,), "0") -> 125.6637 | F39: =IFERROR(VLOOKUP(D39,Capacity!$A$3:$F$532,6,), "0") -> 0.4 | H39: =IFERROR(VLOOKUP(G39,Capacity!$A$3:$D$532,4,), "0") -> 0 | I39: =IFERROR(VLOOKUP(G39,Capacity!$A$3:$F$532,6,), "0") -> 0 | K39: =IFERROR(VLOOKUP(J39,Capacity!$A$3:$D$532,4,), "0") -> 0 | L39: =IFERROR(VLOOKUP(J39,Capacity!$A$3:$F$532,6,), "0") -> 0 | M39: =$E39+$H39+$K39 -> 125.6637 | N39: =$F39+$I39+$L39 -> 0.4 | O39: 87 | P39: =IFERROR(VLOOKUP(O39,Capacity!$A$3:$D$532,4,), "0") -> 388.77208 | Q39: =IFERROR(VLOOKUP(O39,Capacity!$A$3:$F$532,6,), "0") -> 0.75 | R39: =$P39 -> 388.77208 | S39: =$Q39 -> 0.75 | U39: 48 | V39: 1 | W39: 1 | X39: 1 | AB39: =($M39/$R39) -> 0.32323232 | AC39: =($M39/$B39) -> 0.31604938 | AD39: =($N39/$S39) -> 0.53333333 | AE39: =($N39/$C39) -> 0.53333333 | AG39: =$M39/($R39+$B39) -> 0.15980025
A40: 419 | B40: =IFERROR(VLOOKUP(A40,Capacity!$A$3:$D$532,4,), "0") -> 21.16648 | C40: =IFERROR(VLOOKUP(A40,Capacity!$A$3:$F$532,6,), "0") -> 0.175 | E40: =IFERROR(VLOOKUP(D40,Capacity!$A$3:$D$532,4,), "0") -> 0 | F40: =IFERROR(VLOOKUP(D40,Capacity!$A$3:$F$532,6,), "0") -> 0 | H40: =IFERROR(VLOOKUP(G40,Capacity!$A$3:$D$532,4,), "0") -> 0 | I40: =IFERROR(VLOOKUP(G40,Capacity!$A$3:$F$532,6,), "0") -> 0 | K40: =IFERROR(VLOOKUP(J40,Capacity!$A$3:$D$532,4,), "0") -> 0 | L40: =IFERROR(VLOOKUP(J40,Capacity!$A$3:$F$532,6,), "0") -> 0 | M40: =$E40+$H40+$K40 -> 0 | N40: =$F40+$I40+$L40 -> 0 | O40: 159 | P40: =IFERROR(VLOOKUP(O40,Capacity!$A$3:$D$532,4,), "0") -> 22.619467 | Q40: =IFERROR(VLOOKUP(O40,Capacity!$A$3:$F$532,6,), "0") -> 0.3 | R40: =$P40 -> 22.619467 | S40: =$Q40 -> 0.3 | U40: 419 | V40: 0 | W40: 0 | X40: 1 | AB40: =($M40/$R40) -> 0 | AC40: =($M40/$B40) -> 0 | AD40: =($N40/$S40) -> 0 | AE40: =($N40/$C40) -> 0 | AG40: =$M40/($R40+$B40) -> 0
...

Sheet Sheet2
A1: ;;Link | B1: Volume | C1: Diameter | D1: Input | F1: Weighted-D | I1: Weighted-D | L1: Weighted-D | M1: SUM-UP | N1: SUM-Dup | O1: Output | Q1: Weighted-D | R1: SUM-D | S1: SUM-Dd | T1: Conduit | U1: I1 | V1: Upstreams | W1: Downstreams | X1: A 1-1 | Y1: A 1-2 | Z1: A 2-1 | AA1: A 2-2 | AC1: CPE | AD1: PVI
A2: 158 | B2: =IFERROR(VLOOKUP(A2,Capacity!$A$3:$D$532,4,), "0") -> 785.39815 | C2: =IFERROR(VLOOKUP(A2,Capacity!$A$3:$F$532,6,), "0") -> 1 | D2: 156 | E2: =IFERROR(VLOOKUP(D2,Capacity!$A$3:$D$532,4,), "0") -> 388.77208 | F2: =IFERROR(VLOOKUP(D2,Capacity!$A$3:$F$532,6,), "0") -> 0.75 | G2: 163 | H2: =IFERROR(VLOOKUP(G2,Capacity!$A$3:$D$532,4,), "0") -> 42.725659 | I2: =IFERROR(VLOOKUP(G2,Capacity!$A$3:$F$532,6,), "0") -> 0.4 | J2: 153 | K2: =IFERROR(VLOOKUP(J2,Capacity!$A$3:$D$532,4,), "0") -> 267.03537 | L2: =IFERROR(VLOOKUP(J2,Capacity!$A$3:$F$532,6,), "0") -> 1 | M2: =$E2+$H2+$K2 -> 698.53311 | N2: =$F2+$I2+$L2 -> 2.15 | P2: =IFERROR(VLOOKUP(O2,Capacity!$A$3:$D$532,4,), "0") -> 0 | Q2: =IFERROR(VLOOKUP(O2,Capacity!$A$3:$F$532,6,), "0") -> 0 | R2: =$P2 -> 0 | S2: 0 | T2: 158 | V2: 3 | W2: 0 | X2: =($M2/$R2) -> #DIV/0! | Y2: =($M2/$B2) -> 0.8894 | Z2: =($N2/$S2) -> #DIV/0! | AD2: =U2*AC2 -> 0
A3: 163 | B3: =IFERROR(VLOOKUP(A3,Capacity!$A$3:$D$532,4,), "0") -> 42.725659 | C3: =IFERROR(VLOOKUP(A3,Capacity!$A$3:$F$532,6,), "0") -> 0.4 | D3: 162 | E3: =IFERROR(VLOOKUP(D3,Capacity!$A$3:$D$532,4,), "0") -> 16.355916 | F3: =IFERROR(VLOOKUP(D3,Capacity!$A$3:$F$532,6,), "0") -> 0.175 | G3: 169 | H3: =IFERROR(VLOOKUP(G3,Capacity!$A$3:$D$532,4,), "0") -> 42.725659 | I3: =IFERROR(VLOOKUP(G3,Capacity!$A$3:$F$532,6,), "0") -> 0.4 | K3: =IFERROR(VLOOKUP(J3,Capacity!$A$3:$D$532,4,), "0") -> 0 | L3: =IFERROR(VLOOKUP(J3,Capacity!$A$3:$F$532,6,), "0") -> 0 | M3: =$E3+$H3+$K3 -> 59.081576 | N3: =$F3+$I3+$L3 -> 0.575 | O3: 158 | P3: =IFERROR(VLOOKUP(O3,Capacity!$A$3:$D$532,4,), "0") -> 785.39815 | Q3: =IFERROR(VLOOKUP(O3,Capacity!$A$3:$F$532,6,), "0") -> 1 | R3: =$P3 -> 785.39815 | S3: =$Q3 -> 1 | T3: 163 | U3: 2 | V3: 2 | W3: 1 | X3: =($M3/$R3) -> 0.075225 | Y3: =($M3/$B3) -> 1.3828125 | Z3: =($N3/$S3) -> 0.575 | AA3: =($N3/$C3) -> 1.4375 | AC3: =$M3/($R3+$B3) -> 0.071343892 | AD3: =U3*AC3 -> 0.14268778
A4: 156 | B4: =IFERROR(VLOOKUP(A4,Capacity!$A$3:$D$532,4,), "0") -> 388.77208 | C4: =IFERROR(VLOOKUP(A4,Capacity!$A$3:$F$532,6,), "0") -> 0.75 | D4: 155 | E4: =IFERROR(VLOOKUP(D4,Capacity!$A$3:$D$532,4,), "0") -> 371.10063 | F4: =IFERROR(VLOOKUP(D4,Capacity!$A$3:$F$532,6,), "0") -> 0.75 | G4: 161 | H4: =IFERROR(VLOOKUP(G4,Capacity!$A$3:$D$532,4,), "0") -> 17.649467 | I4: =IFERROR(VLOOKUP(G4,Capacity!$A$3:$F$532,6,), "0") -> 0.265 | K4: =IFERROR(VLOOKUP(J4,Capacity!$A$3:$D$532,4,), "0") -> 0 | L4: =IFERROR(VLOOKUP(J4,Capacity!$A$3:$F$532,6,), "0") -> 0 | M4: =$E4+$H4+$K4 -> 388.75009 | N4: =$F4+$I4+$L4 -> 1.015 | O4: 158 | P4: =IFERROR(VLOOKUP(O4,Capacity!$A$3:$D$532,4,), "0") -> 785.39815 | Q4: =IFERROR(VLOOKUP(O4,Capacity!$A$3:$F$532,6,), "0") -> 1 | R4: =$P4 -> 785.39815 | S4: =$Q4 -> 1 | T4: 156 | U4: 2 | V4: 2 | W4: 1 | X4: =($M4/$R4) -> 0.494972 | Y4: =($M4/$B4) -> 0.99994343 | Z4: =($N4/$S4) -> 1.015 | AA4: =($N4/$C4) -> 1.3533333 | AC4: =$M4/($R4+$B4) -> 0.33108495 | AD4: =U4*AC4 -> 0.6621699
A5: 153 | B5: =IFERROR(VLOOKUP(A5,Capacity!$A$3:$D$532,4,), "0") -> 267.03537 | C5: =IFERROR(VLOOKUP(A5,Capacity!$A$3:$F$532,6,), "0") -> 1 | D5: 152 | E5: =IFERROR(VLOOKUP(D5,Capacity!$A$3:$D$532,4,), "0") -> 25.132741 | F5: =IFERROR(VLOOKUP(D5,Capacity!$A$3:$F$532,6,), "0") -> 0.2 | G5: 149 | H5: =IFERROR(VLOOKUP(G5,Capacity!$A$3:$D$532,4,), "0") -> 267.03537 | I5: =IFERROR(VLOOKUP(G5,Capacity!$A$3:$F$532,6,), "0") -> 1 | K5: =IFERROR(VLOOKUP(J5,Capacity!$A$3:$D$532,4,), "0") -> 0 | L5: =IFERROR(VLOOKUP(J5,Capacity!$A$3:$F$532,6,), "0") -> 0 | M5: =$E5+$H5+$K5 -> 292.16811 | N5: =$F5+$I5+$L5 -> 1.2 | O5: 158 | P5: =IFERROR(VLOOKUP(O5,Capacity!$A$3:$D$532,4,), "0") -> 785.39815 | Q5: =IFERROR(VLOOKUP(O5,Capacity!$A$3:$F$532,6,), "0") -> 1 | R5: =$P5 -> 785.39815 | S5: =$Q5 -> 1 | T5: 153 | U5: 2 | V5: 2 | W5: 1 | X5: =($M5/$R5) -> 0.372 | Y5: =($M5/$B5) -> 1.0941176 | Z5: =($N5/$S5) -> 1.2 | AA5: =($N5/$C5) -> 1.2 | AC5: =$M5/($R5+$B5) -> 0.27761194 | AD5: =U5*AC5 -> 0.55522388
A6: 152 | B6: =IFERROR(VLOOKUP(A6,Capacity!$A$3:$D$532,4,), "0") -> 25.132741 | C6: =IFERROR(VLOOKUP(A6,Capacity!$A$3:$F$532,6,), "0") -> 0.2 | D6: 151 | E6: =IFERROR(VLOOKUP(D6,Capacity!$A$3:$D$532,4,), "0") -> 25.132741 | F6: =IFERROR(VLOOKUP(D6,Capacity!$A$3:$F$532,6,), "0") -> 0.2 | H6: =IFERROR(VLOOKUP(G6,Capacity!$A$3:$D$532,4,), "0") -> 0 | I6: =IFERROR(VLOOKUP(G6,Capacity!$A$3:$F$532,6,), "0") -> 0 | K6: =IFERROR(VLOOKUP(J6,Capacity!$A$3:$D$532,4,), "0") -> 0 | L6: =IFERROR(VLOOKUP(J6,Capacity!$A$3:$F$532,6,), "0") -> 0 | M6: =$E6+$H6+$K6 -> 25.132741 | N6: =$F6+$I6+$L6 -> 0.2 | O6: 153 | P6: =IFERROR(VLOOKUP(O6,Capacity!$A$3:$D$532,4,), "0") -> 267.03537 | Q6: =IFERROR(VLOOKUP(O6,Capacity!$A$3:$F$532,6,), "0") -> 1 | R6: =$P6 -> 267.03537 | S6: =$Q6 -> 1 | T6: 152 | U6: 1 | V6: 1 | W6: 1 | X6: =($M6/$R6) -> 0.094117647 | Y6: =($M6/$B6) -> 1 | Z6: =($N6/$S6) -> 0.2 | AA6: =($N6/$C6) -> 1 | AC6: =$M6/($R6+$B6) -> 0.086021505 | AD6: =U6*AC6 -> 0.086021505
A7: 149 | B7: =IFERROR(VLOOKUP(A7,Capacity!$A$3:$D$532,4,), "0") -> 267.03537 | C7: =IFERROR(VLOOKUP(A7,Capacity!$A$3:$F$532,6,), "0") -> 1 | D7: 148 | E7: =IFERROR(VLOOKUP(D7,Capacity!$A$3:$D$532,4,), "0") -> 23.876104 | F7: =IFERROR(VLOOKUP(D7,Capacity!$A$3:$F$532,6,), "0") -> 0.2 | G7: 144 | H7: =IFERROR(VLOOKUP(G7,Capacity!$A$3:$D$532,4,), "0") -> 267.03537 | I7: =IFERROR(VLOOKUP(G7,Capacity!$A$3:$F$532,6,), "0") -> 1 | K7: =IFERROR(VLOOKUP(J7,Capacity!$A$3:$D$532,4,), "0") -> 0 | L7: =IFERROR(VLOOKUP(J7,Capacity!$A$3:$F$532,6,), "0") -> 0 | M7: =$E7+$H7+$K7 -> 290.91147 | N7: =$F7+$I7+$L7 -> 1.2 | O7: 153 | P7: =IFERROR(VLOOKUP(O7,Capacity!$A$3:$D$532,4,), "0") -> 267.03537 | Q7: =IFERROR(VLOOKUP(O7,Capacity!$A$3:$F$532,6,), "0") -> 1 | R7: =$P7 -> 267.03537 | S7: =$Q7 -> 1 | T7: 149 | U7: 2 | V7: 2 | W7: 1 | X7: =($M7/$R7) -> 1.0894118 | Y7: =($M7/$B7) -> 1.0894118 | Z7: =($N7/$S7) -> 1.2 | AA7: =($N7/$C7) -> 1.2 | AC7: =$M7/($R7+$B7) -> 0.54470588 | AD7: =U7*AC7 -> 1.0894118
A8: 161 | B8: =IFERROR(VLOOKUP(A8,Capacity!$A$3:$D$532,4,), "0") -> 17.649467 | C8: =IFERROR(VLOOKUP(A8,Capacity!$A$3:$F$532,6,), "0") -> 0.265 | D8: 160 | E8: =IFERROR(VLOOKUP(D8,Capacity!$A$3:$D$532,4,), "0") -> 27.017696 | F8: =IFERROR(VLOOKUP(D8,Capacity!$A$3:$F$532,6,), "0") -> 0.2 | H8: =IFERROR(VLOOKUP(G8,Capacity!$A$3:$D$532,4,), "0") -> 0 | I8: =IFERROR(VLOOKUP(G8,Capacity!$A$3:$F$532,6,), "0") -> 0 | K8: =IFERROR(VLOOKUP(J8,Capacity!$A$3:$D$532,4,), "0") -> 0 | L8: =IFERROR(VLOOKUP(J8,Capacity!$A$3:$F$532,6,), "0") -> 0 | M8: =$E8+$H8+$K8 -> 27.017696 | N8: =$F8+$I8+$L8 -> 0.2 | O8: 156 | P8: =IFERROR(VLOOKUP(O8,Capacity!$A$3:$D$532,4,), "0") -> 388.77208 | Q8: =IFERROR(VLOOKUP(O8,Capacity!$A$3:$F$532,6,), "0") -> 0.75 | R8: =$P8 -> 388.77208 | S8: =$Q8 -> 0.75 | T8: 161 | U8: 1 | V8: 1 | W8: 1 | X8: =($M8/$R8) -> 0.069494949 | Y8: =($M8/$B8) -> 1.5307939 | Z8: =($N8/$S8) -> 0.26666667 | AA8: =($N8/$C8) -> 0.75471698 | AC8: =$M8/($R8+$B8) -> 0.066477027 | AD8: =U8*AC8 -> 0.066477027
A9: 155 | B9: =IFERROR(VLOOKUP(A9,Capacity!$A$3:$D$532,4,), "0") -> 371.10063 | C9: =IFERROR(VLOOKUP(A9,Capacity!$A$3:$F$532,6,), "0") -> 0.75 | D9: 154 | E9: =IFERROR(VLOOKUP(D9,Capacity!$A$3:$D$532,4,), "0") -> 388.77208 | F9: =IFERROR(VLOOKUP(D9,Capacity!$A$3:$F$532,6,), "0") -> 0.75 | H9: =IFERROR(VLOOKUP(G9,Capacity!$A$3:$D$532,4,), "0") -> 0 | I9: =IFERROR(VLOOKUP(G9,Capacity!$A$3:$F$532,6,), "0") -> 0 | K9: =IFERROR(VLOOKUP(J9,Capacity!$A$3:$D$532,4,), "0") -> 0 | L9: =IFERROR(VLOOKUP(J9,Capacity!$A$3:$F$532,6,), "0") -> 0 | M9: =$E9+$H9+$K9 -> 388.77208 | N9: =$F9+$I9+$L9 -> 0.75 | O9: 156 | P9: =IFERROR(VLOOKUP(O9,Capacity!$A$3:$D$532,4,), "0") -> 388.77208 | Q9: =IFERROR(VLOOKUP(O9,Capacity!$A$3:$F$532,6,), "0") -> 0.75 | R9: =$P9 -> 388.77208 | S9: =$Q9 -> 0.75 | T9: 155 | U9: 1 | V9: 1 | W9: 1 | X9: =($M9/$R9) -> 1 | Y9: =($M9/$B9) -> 1.047619 | Z9: =($N9/$S9) -> 1 | AA9: =($N9/$C9) -> 1 | AC9: =$M9/($R9+$B9) -> 0.51162791 | AD9: =U9*AC9 -> 0.51162791
A10: 169 | B10: =IFERROR(VLOOKUP(A10,Capacity!$A$3:$D$532,4,), "0") -> 42.725659 | C10: =IFERROR(VLOOKUP(A10,Capacity!$A$3:$F$532,6,), "0") -> 0.4 | D10: 167 | E10: =IFERROR(VLOOKUP(D10,Capacity!$A$3:$D$532,4,), "0") -> 175.30087 | F10: =IFERROR(VLOOKUP(D10,Capacity!$A$3:$F$532,6,), "0") -> 0.6 | G10: 177 | H10: =IFERROR(VLOOKUP(G10,Capacity!$A$3:$D$532,4,), "0") -> 282.74333 | I10: =IFERROR(VLOOKUP(G10,Capacity!$A$3:$F$532,6,), "0") -> 0.75 | K10: =IFERROR(VLOOKUP(J10,Capacity!$A$3:$D$532,4,), "0") -> 0 | L10: =IFERROR(VLOOKUP(J10,Capacity!$A$3:$F$532,6,), "0") -> 0 | M10: =$E10+$H10+$K10 -> 458.0442 | N10: =$F10+$I10+$L10 -> 1.35 | O10: 163 | P10: =IFERROR(VLOOKUP(O10,Capacity!$A$3:$D$532,4,), "0") -> 42.725659 | Q10: =IFERROR(VLOOKUP(O10,Capacity!$A$3:$F$532,6,), "0") -> 0.4 | R10: =$P10 -> 42.725659 | S10: =$Q10 -> 0.4 | T10: 169 | U10: 2 | V10: 2 | W10: 1 | X10: =($M10/$R10) -> 10.720588 | Y10: =($M10/$B10) -> 10.720588 | Z10: =($N10/$S10) -> 3.375 | AA10: =($N10/$C10) -> 3.375 | AC10: =$M10/($R10+$B10) -> 5.3602941 | AD10: =U10*AC10 -> 10.720588
A11: 162 | B11: =IFERROR(VLOOKUP(A11,Capacity!$A$3:$D$532,4,), "0") -> 16.355916 | C11: =IFERROR(VLOOKUP(A11,Capacity!$A$3:$F$532,6,), "0") -> 0.175 | D11: 450 | E11: =IFERROR(VLOOKUP(D11,Capacity!$A$3:$D$532,4,), "0") -> 6.7347891 | F11: =IFERROR(VLOOKUP(D11,Capacity!$A$3:$F$532,6,), "0") -> 0.175 | H11: =IFERROR(VLOOKUP(G11,Capacity!$A$3:$D$532,4,), "0") -> 0 | I11: =IFERROR(VLOOKUP(G11,Capacity!$A$3:$F$532,6,), "0") -> 0 | K11: =IFERROR(VLOOKUP(J11,Capacity!$A$3:$D$532,4,), "0") -> 0 | L11: =IFERROR(VLOOKUP(J11,Capacity!$A$3:$F$532,6,), "0") -> 0 | M11: =$E11+$H11+$K11 -> 6.7347891 | N11: =$F11+$I11+$L11 -> 0.175 | O11: 163 | P11: =IFERROR(VLOOKUP(O11,Capacity!$A$3:$D$532,4,), "0") -> 42.725659 | Q11: =IFERROR(VLOOKUP(O11,Capacity!$A$3:$F$532,6,), "0") -> 0.4 | R11: =$P11 -> 42.725659 | S11: =$Q11 -> 0.4 | T11: 162 | U11: 1 | V11: 1 | W11: 1 | X11: =($M11/$R11) -> 0.15762868 | Y11: =($M11/$B11) -> 0.41176471 | Z11: =($N11/$S11) -> 0.4375 | AA11: =($N11/$C11) -> 1 | AC11: =$M11/($R11+$B11) -> 0.11399136 | AD11: =U11*AC11 -> 0.11399136
A12: 148 | B12: =IFERROR(VLOOKUP(A12,Capacity!$A$3:$D$532,4,), "0") -> 23.876104 | C12: =IFERROR(VLOOKUP(A12,Capacity!$A$3:$F$532,6,), "0") -> 0.2 | D12: 147 | E12: =IFERROR(VLOOKUP(D12,Capacity!$A$3:$D$532,4,), "0") -> 23.876104 | F12: =IFERROR(VLOOKUP(D12,Capacity!$A$3:$F$532,6,), "0") -> 0.2 | H12: =IFERROR(VLOOKUP(G12,Capacity!$A$3:$D$532,4,), "0") -> 0 | I12: =IFERROR(VLOOKUP(G12,Capacity!$A$3:$F$532,6,), "0") -> 0 | K12: =IFERROR(VLOOKUP(J12,Capacity!$A$3:$D$532,4,), "0") -> 0 | L12: =IFERROR(VLOOKUP(J12,Capacity!$A$3:$F$532,6,), "0") -> 0 | M12: =$E12+$H12+$K12 -> 23.876104 | N12: =$F12+$I12+$L12 -> 0.2 | O12: 149 | P12: =IFERROR(VLOOKUP(O12,Capacity!$A$3:$D$532,4,), "0") -> 267.03537 | Q12: =IFERROR(VLOOKUP(O12,Capacity!$A$3:$F$532,6,), "0") -> 1 | R12: =$P12 -> 267.03537 | S12: =$Q12 -> 1 | T12: 148 | U12: 1 | V12: 1 | W12: 1 | X12: =($M12/$R12) -> 0.089411765 | Y12: =($M12/$B12) -> 1 | Z12: =($N12/$S12) -> 0.2 | AA12: =($N12/$C12) -> 1 | AC12: =$M12/($R12+$B12) -> 0.082073434 | AD12: =U12*AC12 -> 0.082073434
A13: 144 | B13: =IFERROR(VLOOKUP(A13,Capacity!$A$3:$D$532,4,), "0") -> 267.03537 | C13: =IFERROR(VLOOKUP(A13,Capacity!$A$3:$F$532,6,), "0") -> 1 | D13: 143 | E13: =IFERROR(VLOOKUP(D13,Capacity!$A$3:$D$532,4,), "0") -> 17.799086 | F13: =IFERROR(VLOOKUP(D13,Capacity!$A$3:$F$532,6,), "0") -> 0.175 | G13: 137 | H13: =IFERROR(VLOOKUP(G13,Capacity!$A$3:$D$532,4,), "0") -> 267.03537 | I13: =IFERROR(VLOOKUP(G13,Capacity!$A$3:$F$532,6,), "0") -> 1 | K13: =IFERROR(VLOOKUP(J13,Capacity!$A$3:$D$532,4,), "0") -> 0 | L13: =IFERROR(VLOOKUP(J13,Capacity!$A$3:$F$532,6,), "0") -> 0 | M13: =$E13+$H13+$K13 -> 284.83446 | N13: =$F13+$I13+$L13 -> 1.175 | O13: 149 | P13: =IFERROR(VLOOKUP(O13,Capacity!$A$3:$D$532,4,), "0") -> 267.03537 | Q13: =IFERROR(VLOOKUP(O13,Capacity!$A$3:$F$532,6,), "0") -> 1 | R13: =$P13 -> 267.03537 | S13: =$Q13 -> 1 | T13: 144 | U13: 2 | V13: 2 | W13: 1 | X13: =($M13/$R13) -> 1.0666544 | Y13: =($M13/$B13) -> 1.0666544 | Z13: =($N13/$S13) -> 1.175 | AA13: =($N13/$C13) -> 1.175 | AC13: =$M13/($R13+$B13) -> 0.53332721 | AD13: =U13*AC13 -> 1.0666544
